package atlantismod.common.structures;

import java.util.Random;

import atlantismod.common.AtlantisMod;
import net.minecraft.block.Block;
import net.minecraft.world.World;
import net.minecraft.world.gen.feature.WorldGenerator;

public class WorldGenReef2 extends WorldGenerator {

	public boolean LocationIsValidSpawn(World world, int i, int j, int k){
		return (world.getBlockId(i, j, k) == Block.waterStill.blockID);
	}

	public boolean generate(World world, Random rand, int i, int j, int k) {
		j -= 11;
		if(LocationIsValidSpawn(world, i, j+5, k) && LocationIsValidSpawn(world, i + 18, j+5, k) && LocationIsValidSpawn(world, i + 18, j+5, k + 20) && LocationIsValidSpawn(world, i, j+5, k + 20)) {

			world.setBlock(i + 3, j + 0, k + 11, AtlantisMod.blockCoralOrange.blockID);
			world.setBlock(i + 4, j + 0, k + 11, AtlantisMod.blockCoralOrange.blockID);
			world.setBlock(i + 4, j + 0, k + 12, AtlantisMod.blockCoralOrange.blockID);
			world.setBlock(i + 4, j + 1, k + 11, AtlantisMod.blockCoralOrange.blockID);
			world.setBlock(i + 4, j + 2, k + 14, AtlantisMod.blockCoralOrange.blockID);
			world.setBlock(i + 5, j + 0, k + 8, AtlantisMod.blockCoralOrange.blockID);
			world.setBlock(i + 5, j + 0, k + 11, AtlantisMod.blockCoralOrange.blockID);
			world.setBlock(i + 5, j + 0, k + 12, AtlantisMod.blockCoralOrange.blockID);
			world.setBlock(i + 5, j + 0, k + 13, AtlantisMod.blockCoralOrange.blockID);
			world.setBlock(i + 5, j + 0, k + 14, AtlantisMod.blockCoralOrange.blockID);
			world.setBlock(i + 5, j + 0, k + 15, AtlantisMod.blockCoralOrange.blockID);
			world.setBlock(i + 5, j + 1, k + 8, AtlantisMod.blockCoralOrange.blockID);
			world.setBlock(i + 5, j + 1, k + 11, AtlantisMod.blockCoralOrange.blockID);
			world.setBlock(i + 5, j + 1, k + 12, AtlantisMod.blockCoralOrange.blockID);
			world.setBlock(i + 5, j + 1, k + 13, AtlantisMod.blockCoralOrange.blockID);
			world.setBlock(i + 5, j + 1, k + 14, AtlantisMod.blockCoralOrange.blockID);
			world.setBlock(i + 5, j + 2, k + 12, AtlantisMod.blockCoralOrange.blockID);
			world.setBlock(i + 5, j + 2, k + 13, AtlantisMod.blockCoralOrange.blockID);
			world.setBlock(i + 5, j + 2, k + 14, AtlantisMod.blockCoralOrange.blockID);
			world.setBlock(i + 5, j + 3, k + 9, AtlantisMod.blockCoralOrange.blockID);
			world.setBlock(i + 5, j + 3, k + 14, AtlantisMod.blockCoralOrange.blockID);
			world.setBlock(i + 6, j + 0, k + 7, AtlantisMod.blockCoralOrange.blockID);
			world.setBlock(i + 6, j + 0, k + 8, AtlantisMod.blockCoralOrange.blockID);
			world.setBlock(i + 6, j + 0, k + 9, AtlantisMod.blockCoralOrange.blockID);
			world.setBlock(i + 6, j + 0, k + 10, AtlantisMod.blockCoralOrange.blockID);
			world.setBlock(i + 6, j + 0, k + 11, AtlantisMod.blockCoralOrange.blockID);
			world.setBlock(i + 6, j + 0, k + 12, AtlantisMod.blockCoralOrange.blockID);
			world.setBlock(i + 6, j + 0, k + 13, AtlantisMod.blockCoralOrange.blockID);
			world.setBlock(i + 6, j + 0, k + 14, AtlantisMod.blockCoralOrange.blockID);
			world.setBlock(i + 6, j + 0, k + 15, AtlantisMod.blockCoralOrange.blockID);
			world.setBlock(i + 6, j + 1, k + 8, AtlantisMod.blockCoralOrange.blockID);
			world.setBlock(i + 6, j + 1, k + 9, AtlantisMod.blockCoralOrange.blockID);
			world.setBlock(i + 6, j + 1, k + 11, AtlantisMod.blockCoralOrange.blockID);
			world.setBlock(i + 6, j + 1, k + 13, AtlantisMod.blockCoralOrange.blockID);
			world.setBlock(i + 6, j + 1, k + 15, AtlantisMod.blockCoralOrange.blockID);
			world.setBlock(i + 6, j + 2, k + 8, AtlantisMod.blockCoralOrange.blockID);
			world.setBlock(i + 6, j + 2, k + 9, AtlantisMod.blockCoralOrange.blockID);
			world.setBlock(i + 6, j + 2, k + 11, AtlantisMod.blockCoralOrange.blockID);
			world.setBlock(i + 6, j + 2, k + 12, AtlantisMod.blockCoralOrange.blockID);
			world.setBlock(i + 6, j + 2, k + 14, AtlantisMod.blockCoralOrange.blockID);
			world.setBlock(i + 6, j + 3, k + 9, AtlantisMod.blockCoralOrange.blockID);
			world.setBlock(i + 7, j + 0, k + 10, AtlantisMod.blockCoralOrange.blockID);
			world.setBlock(i + 7, j + 0, k + 11, AtlantisMod.blockCoralOrange.blockID);
			world.setBlock(i + 7, j + 0, k + 12, AtlantisMod.blockCoralOrange.blockID);
			world.setBlock(i + 7, j + 0, k + 13, AtlantisMod.blockCoralOrange.blockID);
			world.setBlock(i + 7, j + 0, k + 14, AtlantisMod.blockCoralOrange.blockID);
			world.setBlock(i + 7, j + 0, k + 15, AtlantisMod.blockCoralOrange.blockID);
			world.setBlock(i + 7, j + 0, k + 16, AtlantisMod.blockCoralOrange.blockID);
			world.setBlock(i + 7, j + 1, k + 9, AtlantisMod.blockCoralOrange.blockID);
			world.setBlock(i + 7, j + 1, k + 10, AtlantisMod.blockCoralOrange.blockID);
			world.setBlock(i + 7, j + 1, k + 11, AtlantisMod.blockCoralOrange.blockID);
			world.setBlock(i + 7, j + 1, k + 12, AtlantisMod.blockCoralOrange.blockID);
			world.setBlock(i + 7, j + 1, k + 13, AtlantisMod.blockCoralOrange.blockID);
			world.setBlock(i + 7, j + 1, k + 14, AtlantisMod.blockCoralOrange.blockID);
			world.setBlock(i + 7, j + 1, k + 15, AtlantisMod.blockCoralOrange.blockID);
			world.setBlock(i + 7, j + 1, k + 16, AtlantisMod.blockCoralOrange.blockID);
			world.setBlock(i + 7, j + 2, k + 9, AtlantisMod.blockCoralOrange.blockID);
			world.setBlock(i + 7, j + 2, k + 10, AtlantisMod.blockCoralOrange.blockID);
			world.setBlock(i + 7, j + 2, k + 11, AtlantisMod.blockCoralOrange.blockID);
			world.setBlock(i + 7, j + 2, k + 12, AtlantisMod.blockCoralOrange.blockID);
			world.setBlock(i + 7, j + 2, k + 14, AtlantisMod.blockCoralOrange.blockID);
			world.setBlock(i + 7, j + 2, k + 16, AtlantisMod.blockCoralOrange.blockID);
			world.setBlock(i + 7, j + 3, k + 9, AtlantisMod.blockCoralOrange.blockID);
			world.setBlock(i + 7, j + 3, k + 11, AtlantisMod.blockCoralOrange.blockID);
			world.setBlock(i + 7, j + 3, k + 16, AtlantisMod.blockCoralOrange.blockID);
			world.setBlock(i + 8, j + 0, k + 10, AtlantisMod.blockCoralOrange.blockID);
			world.setBlock(i + 8, j + 0, k + 11, AtlantisMod.blockCoralOrange.blockID);
			world.setBlock(i + 8, j + 0, k + 12, AtlantisMod.blockCoralOrange.blockID);
			world.setBlock(i + 8, j + 0, k + 13, AtlantisMod.blockCoralOrange.blockID);
			world.setBlock(i + 8, j + 0, k + 14, AtlantisMod.blockCoralOrange.blockID);
			world.setBlock(i + 8, j + 0, k + 15, AtlantisMod.blockCoralOrange.blockID);
			world.setBlock(i + 8, j + 0, k + 16, AtlantisMod.blockCoralOrange.blockID);
			world.setBlock(i + 8, j + 0, k + 17, AtlantisMod.blockCoralOrange.blockID);
			world.setBlock(i + 8, j + 1, k + 8, AtlantisMod.blockCoralOrange.blockID);
			world.setBlock(i + 8, j + 1, k + 9, AtlantisMod.blockCoralOrange.blockID);
			world.setBlock(i + 8, j + 1, k + 10, AtlantisMod.blockCoralOrange.blockID);
			world.setBlock(i + 8, j + 1, k + 11, AtlantisMod.blockCoralOrange.blockID);
			world.setBlock(i + 8, j + 1, k + 12, AtlantisMod.blockCoralOrange.blockID);
			world.setBlock(i + 8, j + 1, k + 13, AtlantisMod.blockCoralOrange.blockID);
			world.setBlock(i + 8, j + 1, k + 14, AtlantisMod.blockCoralOrange.blockID);
			world.setBlock(i + 8, j + 2, k + 8, AtlantisMod.blockCoralOrange.blockID);
			world.setBlock(i + 8, j + 2, k + 9, AtlantisMod.blockCoralOrange.blockID);
			world.setBlock(i + 8, j + 2, k + 11, AtlantisMod.blockCoralOrange.blockID);
			world.setBlock(i + 8, j + 2, k + 13, AtlantisMod.blockCoralOrange.blockID);
			world.setBlock(i + 8, j + 2, k + 14, AtlantisMod.blockCoralOrange.blockID);
			world.setBlock(i + 8, j + 3, k + 14, AtlantisMod.blockCoralOrange.blockID);
			world.setBlock(i + 9, j + 0, k + 8, AtlantisMod.blockCoralOrange.blockID);
			world.setBlock(i + 9, j + 0, k + 9, AtlantisMod.blockCoralOrange.blockID);
			world.setBlock(i + 9, j + 0, k + 10, AtlantisMod.blockCoralOrange.blockID);
			world.setBlock(i + 9, j + 0, k + 11, AtlantisMod.blockCoralOrange.blockID);
			world.setBlock(i + 9, j + 0, k + 12, AtlantisMod.blockCoralOrange.blockID);
			world.setBlock(i + 9, j + 0, k + 13, AtlantisMod.blockCoralOrange.blockID);
			world.setBlock(i + 9, j + 0, k + 14, AtlantisMod.blockCoralOrange.blockID);
			world.setBlock(i + 9, j + 1, k + 8, AtlantisMod.blockCoralOrange.blockID);
			world.setBlock(i + 9, j + 1, k + 9, AtlantisMod.blockCoralOrange.blockID);
			world.setBlock(i + 9, j + 1, k + 12, AtlantisMod.blockCoralOrange.blockID);
			world.setBlock(i + 9, j + 2, k + 8, AtlantisMod.blockCoralOrange.blockID);
			world.setBlock(i + 9, j + 2, k + 9, AtlantisMod.blockCoralOrange.blockID);
			world.setBlock(i + 9, j + 3, k + 8, AtlantisMod.blockCoralOrange.blockID);
			world.setBlock(i + 9, j + 3, k + 12, AtlantisMod.blockCoralOrange.blockID);
			world.setBlock(i + 10, j + 0, k + 7, AtlantisMod.blockCoralOrange.blockID);
			world.setBlock(i + 10, j + 0, k + 8, AtlantisMod.blockCoralOrange.blockID);
			world.setBlock(i + 10, j + 0, k + 9, AtlantisMod.blockCoralOrange.blockID);
			world.setBlock(i + 10, j + 0, k + 10, AtlantisMod.blockCoralOrange.blockID);
			world.setBlock(i + 10, j + 0, k + 11, AtlantisMod.blockCoralOrange.blockID);
			world.setBlock(i + 10, j + 0, k + 12, AtlantisMod.blockCoralOrange.blockID);
			world.setBlock(i + 10, j + 0, k + 13, AtlantisMod.blockCoralOrange.blockID);
			world.setBlock(i + 10, j + 1, k + 8, AtlantisMod.blockCoralOrange.blockID);
			world.setBlock(i + 10, j + 1, k + 9, AtlantisMod.blockCoralOrange.blockID);
			world.setBlock(i + 10, j + 1, k + 13, AtlantisMod.blockCoralOrange.blockID);
			world.setBlock(i + 10, j + 2, k + 9, AtlantisMod.blockCoralOrange.blockID);
			world.setBlock(i + 10, j + 2, k + 10, AtlantisMod.blockCoralOrange.blockID);
			world.setBlock(i + 10, j + 2, k + 12, AtlantisMod.blockCoralOrange.blockID);
			world.setBlock(i + 10, j + 3, k + 10, AtlantisMod.blockCoralOrange.blockID);
			world.setBlock(i + 10, j + 3, k + 12, AtlantisMod.blockCoralOrange.blockID);
			world.setBlock(i + 11, j + 0, k + 6, AtlantisMod.blockCoralOrange.blockID);
			world.setBlock(i + 11, j + 0, k + 7, AtlantisMod.blockCoralOrange.blockID);
			world.setBlock(i + 11, j + 0, k + 8, AtlantisMod.blockCoralOrange.blockID);
			world.setBlock(i + 11, j + 0, k + 9, AtlantisMod.blockCoralOrange.blockID);
			world.setBlock(i + 11, j + 0, k + 10, AtlantisMod.blockCoralOrange.blockID);
			world.setBlock(i + 11, j + 0, k + 11, AtlantisMod.blockCoralOrange.blockID);
			world.setBlock(i + 11, j + 0, k + 12, AtlantisMod.blockCoralOrange.blockID);
			world.setBlock(i + 11, j + 0, k + 13, AtlantisMod.blockCoralOrange.blockID);
			world.setBlock(i + 11, j + 1, k + 7, AtlantisMod.blockCoralOrange.blockID);
			world.setBlock(i + 11, j + 1, k + 9, AtlantisMod.blockCoralOrange.blockID);
			world.setBlock(i + 11, j + 1, k + 10, AtlantisMod.blockCoralOrange.blockID);
			world.setBlock(i + 11, j + 1, k + 12, AtlantisMod.blockCoralOrange.blockID);
			world.setBlock(i + 11, j + 2, k + 9, AtlantisMod.blockCoralOrange.blockID);
			world.setBlock(i + 11, j + 2, k + 10, AtlantisMod.blockCoralOrange.blockID);
			world.setBlock(i + 11, j + 2, k + 11, AtlantisMod.blockCoralOrange.blockID);
			world.setBlock(i + 11, j + 2, k + 12, AtlantisMod.blockCoralOrange.blockID);
			world.setBlock(i + 12, j + 0, k + 6, AtlantisMod.blockCoralOrange.blockID);
			world.setBlock(i + 12, j + 0, k + 7, AtlantisMod.blockCoralOrange.blockID);
			world.setBlock(i + 12, j + 0, k + 8, AtlantisMod.blockCoralOrange.blockID);
			world.setBlock(i + 12, j + 0, k + 9, AtlantisMod.blockCoralOrange.blockID);
			world.setBlock(i + 12, j + 0, k + 10, AtlantisMod.blockCoralOrange.blockID);
			world.setBlock(i + 12, j + 0, k + 11, AtlantisMod.blockCoralOrange.blockID);
			world.setBlock(i + 12, j + 0, k + 12, AtlantisMod.blockCoralOrange.blockID);
			world.setBlock(i + 12, j + 0, k + 13, AtlantisMod.blockCoralOrange.blockID);
			world.setBlock(i + 12, j + 1, k + 7, AtlantisMod.blockCoralOrange.blockID);
			world.setBlock(i + 12, j + 1, k + 8, AtlantisMod.blockCoralOrange.blockID);
			world.setBlock(i + 12, j + 1, k + 9, AtlantisMod.blockCoralOrange.blockID);
			world.setBlock(i + 12, j + 1, k + 10, AtlantisMod.blockCoralOrange.blockID);
			world.setBlock(i + 12, j + 1, k + 11, AtlantisMod.blockCoralOrange.blockID);
			world.setBlock(i + 12, j + 1, k + 12, AtlantisMod.blockCoralOrange.blockID);
			world.setBlock(i + 12, j + 2, k + 8, AtlantisMod.blockCoralOrange.blockID);
			world.setBlock(i + 12, j + 2, k + 11, AtlantisMod.blockCoralOrange.blockID);
			world.setBlock(i + 12, j + 2, k + 12, AtlantisMod.blockCoralOrange.blockID);
			world.setBlock(i + 13, j + 0, k + 8, AtlantisMod.blockCoralOrange.blockID);
			world.setBlock(i + 13, j + 0, k + 9, AtlantisMod.blockCoralOrange.blockID);
			world.setBlock(i + 13, j + 0, k + 10, AtlantisMod.blockCoralOrange.blockID);
			world.setBlock(i + 13, j + 0, k + 11, AtlantisMod.blockCoralOrange.blockID);
			world.setBlock(i + 13, j + 0, k + 12, AtlantisMod.blockCoralOrange.blockID);
			world.setBlock(i + 13, j + 1, k + 10, AtlantisMod.blockCoralOrange.blockID);
			world.setBlock(i + 13, j + 1, k + 12, AtlantisMod.blockCoralOrange.blockID);
			world.setBlock(i + 13, j + 1, k + 13, AtlantisMod.blockCoralOrange.blockID);
			world.setBlock(i + 13, j + 2, k + 10, AtlantisMod.blockCoralOrange.blockID);
			world.setBlock(i + 13, j + 2, k + 11, AtlantisMod.blockCoralOrange.blockID);
			world.setBlock(i + 13, j + 2, k + 12, AtlantisMod.blockCoralOrange.blockID);
			world.setBlock(i + 13, j + 3, k + 10, AtlantisMod.blockCoralOrange.blockID);
			world.setBlock(i + 13, j + 3, k + 12, AtlantisMod.blockCoralOrange.blockID);
			world.setBlock(i + 14, j + 0, k + 11, AtlantisMod.blockCoralOrange.blockID);
			world.setBlock(i + 14, j + 0, k + 12, AtlantisMod.blockCoralOrange.blockID);
			world.setBlock(i + 14, j + 0, k + 13, AtlantisMod.blockCoralOrange.blockID);
			world.setBlock(i + 14, j + 1, k + 13, AtlantisMod.blockCoralOrange.blockID);
			world.setBlock(i + 15, j + 0, k + 13, AtlantisMod.blockCoralOrange.blockID);
	
			return true;
		}
		return false;
	}
}