package atlantismod.common.structures;

import java.util.Random;
import net.minecraft.block.Block;
import net.minecraft.world.World;
import net.minecraft.world.gen.feature.WorldGenerator;

public class WorldGenShipwreck extends WorldGenerator {
	public boolean LocationIsValidSpawn(World world, int i, int j, int k){
		return (world.getBlockId(i, j, k) == Block.waterStill.blockID);
	}

	@Override
	public boolean generate(World world, Random rand, int i, int j, int k) {
		if(!(LocationIsValidSpawn(world, i, j + 14, k) && LocationIsValidSpawn(world, i + 18, j + 14, k) && LocationIsValidSpawn(world, i + 18, j + 14, k + 35) && LocationIsValidSpawn(world, i, j + 14, k + 35))) return false;
		world.setBlock(i + 0, j + 2, k + 14, Block.fence.blockID);
		world.setBlock(i + 0, j + 2, k + 15, Block.fence.blockID);
		world.setBlock(i + 0, j + 3, k + 14, Block.fence.blockID);
		world.setBlock(i + 0, j + 3, k + 15, Block.fence.blockID);
		world.setBlock(i + 0, j + 4, k + 14, Block.fence.blockID);
		world.setBlock(i + 0, j + 4, k + 15, Block.fence.blockID);
		world.setBlock(i + 0, j + 5, k + 14, Block.fence.blockID);
		world.setBlock(i + 0, j + 5, k + 15, Block.fence.blockID);
		world.setBlock(i + 0, j + 6, k + 14, Block.fence.blockID);
		world.setBlock(i + 0, j + 6, k + 15, Block.fence.blockID);
		world.setBlock(i + 0, j + 7, k + 14, Block.fence.blockID);
		world.setBlock(i + 0, j + 7, k + 15, Block.fence.blockID);
		world.setBlock(i + 0, j + 8, k + 14, Block.fence.blockID);
		world.setBlock(i + 0, j + 8, k + 15, Block.fence.blockID);
		world.setBlock(i + 0, j + 9, k + 14, Block.fence.blockID);
		world.setBlock(i + 0, j + 9, k + 15, Block.fence.blockID);
		world.setBlock(i + 0, j + 10, k + 14, Block.fence.blockID);
		world.setBlock(i + 0, j + 10, k + 15, Block.fence.blockID);
		world.setBlock(i + 0, j + 11, k + 14, Block.fence.blockID);
		world.setBlock(i + 0, j + 11, k + 15, Block.fence.blockID);
		world.setBlock(i + 0, j + 12, k + 14, Block.fence.blockID);
		world.setBlock(i + 0, j + 12, k + 15, Block.fence.blockID);
		world.setBlock(i + 0, j + 13, k + 14, Block.fence.blockID);
		world.setBlock(i + 0, j + 13, k + 15, Block.fence.blockID);
		world.setBlock(i + 1, j + 3, k + 14, Block.cloth.blockID);
		world.setBlock(i + 1, j + 3, k + 15, Block.cloth.blockID);
		world.setBlock(i + 1, j + 4, k + 14, Block.cloth.blockID);
		world.setBlock(i + 1, j + 4, k + 15, Block.cloth.blockID);
		world.setBlock(i + 1, j + 5, k + 14, Block.cloth.blockID);
		world.setBlock(i + 1, j + 5, k + 15, Block.cloth.blockID);
		world.setBlock(i + 1, j + 6, k + 14, Block.cloth.blockID);
		world.setBlock(i + 1, j + 6, k + 15, Block.cloth.blockID);
		world.setBlock(i + 1, j + 7, k + 14, Block.fence.blockID);
		world.setBlock(i + 1, j + 7, k + 15, Block.fence.blockID);
		world.setBlock(i + 1, j + 8, k + 14, Block.fence.blockID);
		world.setBlock(i + 1, j + 8, k + 15, Block.fence.blockID);
		world.setBlock(i + 1, j + 9, k + 14, Block.cloth.blockID);
		world.setBlock(i + 1, j + 9, k + 15, Block.cloth.blockID);
		world.setBlock(i + 1, j + 10, k + 14, Block.cloth.blockID);
		world.setBlock(i + 1, j + 10, k + 15, Block.cloth.blockID);
		world.setBlock(i + 1, j + 11, k + 14, Block.cloth.blockID);
		world.setBlock(i + 1, j + 11, k + 15, Block.cloth.blockID);
		world.setBlock(i + 1, j + 12, k + 14, Block.cloth.blockID);
		world.setBlock(i + 1, j + 12, k + 15, Block.cloth.blockID);
		world.setBlock(i + 2, j + 3, k + 9, Block.fence.blockID);
		world.setBlock(i + 2, j + 3, k + 10, Block.fence.blockID);
		world.setBlock(i + 2, j + 3, k + 14, Block.cloth.blockID);
		world.setBlock(i + 2, j + 3, k + 15, Block.cloth.blockID);
		world.setBlock(i + 2, j + 3, k + 19, Block.fence.blockID);
		world.setBlock(i + 2, j + 3, k + 20, Block.fence.blockID);
		world.setBlock(i + 2, j + 4, k + 9, Block.fence.blockID);
		world.setBlock(i + 2, j + 4, k + 10, Block.fence.blockID);
		world.setBlock(i + 2, j + 4, k + 14, Block.cloth.blockID);
		world.setBlock(i + 2, j + 4, k + 19, Block.fence.blockID);
		world.setBlock(i + 2, j + 4, k + 20, Block.fence.blockID);
		world.setBlock(i + 2, j + 5, k + 9, Block.fence.blockID);
		world.setBlock(i + 2, j + 5, k + 10, Block.fence.blockID);
		world.setBlock(i + 2, j + 5, k + 14, Block.cloth.blockID);
		world.setBlock(i + 2, j + 5, k + 15, Block.cloth.blockID);
		world.setBlock(i + 2, j + 5, k + 19, Block.fence.blockID);
		world.setBlock(i + 2, j + 5, k + 20, Block.fence.blockID);
		world.setBlock(i + 2, j + 6, k + 9, Block.fence.blockID);
		world.setBlock(i + 2, j + 6, k + 10, Block.fence.blockID);
		world.setBlock(i + 2, j + 6, k + 14, Block.cloth.blockID);
		world.setBlock(i + 2, j + 6, k + 15, Block.cloth.blockID);
		world.setBlock(i + 2, j + 6, k + 19, Block.fence.blockID);
		world.setBlock(i + 2, j + 6, k + 20, Block.fence.blockID);
		world.setBlock(i + 2, j + 7, k + 9, Block.fence.blockID);
		world.setBlock(i + 2, j + 7, k + 10, Block.fence.blockID);
		world.setBlock(i + 2, j + 7, k + 14, Block.fence.blockID);
		world.setBlock(i + 2, j + 7, k + 15, Block.fence.blockID);
		world.setBlock(i + 2, j + 7, k + 19, Block.fence.blockID);
		world.setBlock(i + 2, j + 7, k + 20, Block.fence.blockID);
		world.setBlock(i + 2, j + 8, k + 9, Block.fence.blockID);
		world.setBlock(i + 2, j + 8, k + 10, Block.fence.blockID);
		world.setBlock(i + 2, j + 8, k + 14, Block.fence.blockID);
		world.setBlock(i + 2, j + 8, k + 15, Block.fence.blockID);
		world.setBlock(i + 2, j + 8, k + 19, Block.fence.blockID);
		world.setBlock(i + 2, j + 8, k + 20, Block.fence.blockID);
		world.setBlock(i + 2, j + 9, k + 9, Block.fence.blockID);
		world.setBlock(i + 2, j + 9, k + 10, Block.fence.blockID);
		world.setBlock(i + 2, j + 9, k + 14, Block.cloth.blockID);
		world.setBlock(i + 2, j + 9, k + 15, Block.cloth.blockID);
		world.setBlock(i + 2, j + 9, k + 19, Block.fence.blockID);
		world.setBlock(i + 2, j + 9, k + 20, Block.fence.blockID);
		world.setBlock(i + 2, j + 10, k + 9, Block.fence.blockID);
		world.setBlock(i + 2, j + 10, k + 10, Block.fence.blockID);
		world.setBlock(i + 2, j + 10, k + 15, Block.cloth.blockID);
		world.setBlock(i + 2, j + 10, k + 19, Block.fence.blockID);
		world.setBlock(i + 2, j + 10, k + 20, Block.fence.blockID);
		world.setBlock(i + 2, j + 11, k + 9, Block.fence.blockID);
		world.setBlock(i + 2, j + 11, k + 10, Block.fence.blockID);
		world.setBlock(i + 2, j + 11, k + 19, Block.fence.blockID);
		world.setBlock(i + 2, j + 11, k + 20, Block.fence.blockID);
		world.setBlock(i + 2, j + 12, k + 9, Block.fence.blockID);
		world.setBlock(i + 2, j + 12, k + 10, Block.fence.blockID);
		world.setBlock(i + 2, j + 12, k + 14, Block.cloth.blockID);
		world.setBlock(i + 2, j + 12, k + 15, Block.cloth.blockID);
		world.setBlock(i + 2, j + 12, k + 19, Block.fence.blockID);
		world.setBlock(i + 2, j + 12, k + 20, Block.fence.blockID);
		world.setBlock(i + 3, j + 3, k + 14, Block.cloth.blockID);
		world.setBlock(i + 3, j + 3, k + 15, Block.cloth.blockID);
		world.setBlock(i + 3, j + 4, k + 9, Block.cloth.blockID);
		world.setBlock(i + 3, j + 4, k + 10, Block.cloth.blockID);
		world.setBlock(i + 3, j + 4, k + 14, Block.cloth.blockID);
		world.setBlock(i + 3, j + 4, k + 15, Block.cloth.blockID);
		world.setBlock(i + 3, j + 4, k + 19, Block.cloth.blockID);
		world.setBlock(i + 3, j + 4, k + 20, Block.cloth.blockID);
		world.setBlock(i + 3, j + 5, k + 9, Block.cloth.blockID);
		world.setBlock(i + 3, j + 5, k + 10, Block.cloth.blockID);
		world.setBlock(i + 3, j + 5, k + 14, Block.cloth.blockID);
		world.setBlock(i + 3, j + 5, k + 15, Block.cloth.blockID);
		world.setBlock(i + 3, j + 5, k + 19, Block.cloth.blockID);
		world.setBlock(i + 3, j + 5, k + 20, Block.cloth.blockID);
		world.setBlock(i + 3, j + 6, k + 9, Block.cloth.blockID);
		world.setBlock(i + 3, j + 6, k + 10, Block.cloth.blockID);
		world.setBlock(i + 3, j + 6, k + 14, Block.cloth.blockID);
		world.setBlock(i + 3, j + 6, k + 15, Block.cloth.blockID);
		world.setBlock(i + 3, j + 6, k + 19, Block.cloth.blockID);
		world.setBlock(i + 3, j + 6, k + 20, Block.cloth.blockID);
		world.setBlock(i + 3, j + 7, k + 9, Block.fence.blockID);
		world.setBlock(i + 3, j + 7, k + 10, Block.fence.blockID);
		world.setBlock(i + 3, j + 7, k + 14, Block.fence.blockID);
		world.setBlock(i + 3, j + 7, k + 15, Block.fence.blockID);
		world.setBlock(i + 3, j + 7, k + 19, Block.fence.blockID);
		world.setBlock(i + 3, j + 7, k + 20, Block.fence.blockID);
		world.setBlock(i + 3, j + 8, k + 9, Block.fence.blockID);
		world.setBlock(i + 3, j + 8, k + 10, Block.fence.blockID);
		world.setBlock(i + 3, j + 8, k + 14, Block.fence.blockID);
		world.setBlock(i + 3, j + 8, k + 15, Block.fence.blockID);
		world.setBlock(i + 3, j + 8, k + 19, Block.fence.blockID);
		world.setBlock(i + 3, j + 8, k + 20, Block.fence.blockID);
		world.setBlock(i + 3, j + 9, k + 9, Block.cloth.blockID);
		world.setBlock(i + 3, j + 9, k + 10, Block.cloth.blockID);
		world.setBlock(i + 3, j + 9, k + 14, Block.cloth.blockID);
		world.setBlock(i + 3, j + 9, k + 15, Block.cloth.blockID);
		world.setBlock(i + 3, j + 9, k + 19, Block.cloth.blockID);
		world.setBlock(i + 3, j + 9, k + 20, Block.cloth.blockID);
		world.setBlock(i + 3, j + 10, k + 9, Block.cloth.blockID);
		world.setBlock(i + 3, j + 10, k + 10, Block.cloth.blockID);
		world.setBlock(i + 3, j + 10, k + 15, Block.cloth.blockID);
		world.setBlock(i + 3, j + 10, k + 19, Block.cloth.blockID);
		world.setBlock(i + 3, j + 10, k + 20, Block.cloth.blockID);
		world.setBlock(i + 3, j + 11, k + 9, Block.cloth.blockID);
		world.setBlock(i + 3, j + 11, k + 10, Block.cloth.blockID);
		world.setBlock(i + 3, j + 11, k + 14, Block.cloth.blockID);
		world.setBlock(i + 3, j + 11, k + 15, Block.cloth.blockID);
		world.setBlock(i + 3, j + 11, k + 19, Block.cloth.blockID);
		world.setBlock(i + 3, j + 11, k + 20, Block.cloth.blockID);
		world.setBlock(i + 3, j + 12, k + 14, Block.cloth.blockID);
		world.setBlock(i + 3, j + 12, k + 15, Block.cloth.blockID);
		world.setBlock(i + 4, j + 3, k + 15, Block.cloth.blockID);
		world.setBlock(i + 4, j + 4, k + 9, Block.cloth.blockID);
		world.setBlock(i + 4, j + 4, k + 10, Block.cloth.blockID);
		world.setBlock(i + 4, j + 4, k + 14, Block.cloth.blockID);
		world.setBlock(i + 4, j + 4, k + 15, Block.cloth.blockID);
		world.setBlock(i + 4, j + 4, k + 19, Block.cloth.blockID);
		world.setBlock(i + 4, j + 4, k + 20, Block.cloth.blockID);
		world.setBlock(i + 4, j + 5, k + 9, Block.cloth.blockID);
		world.setBlock(i + 4, j + 5, k + 10, Block.cloth.blockID);
		world.setBlock(i + 4, j + 5, k + 14, Block.cloth.blockID);
		world.setBlock(i + 4, j + 5, k + 15, Block.cloth.blockID);
		world.setBlock(i + 4, j + 5, k + 19, Block.cloth.blockID);
		world.setBlock(i + 4, j + 5, k + 20, Block.cloth.blockID);
		world.setBlock(i + 4, j + 6, k + 9, Block.cloth.blockID);
		world.setBlock(i + 4, j + 6, k + 10, Block.cloth.blockID);
		world.setBlock(i + 4, j + 6, k + 14, Block.cloth.blockID);
		world.setBlock(i + 4, j + 6, k + 15, Block.cloth.blockID);
		world.setBlock(i + 4, j + 6, k + 19, Block.cloth.blockID);
		world.setBlock(i + 4, j + 6, k + 20, Block.cloth.blockID);
		world.setBlock(i + 4, j + 7, k + 9, Block.fence.blockID);
		world.setBlock(i + 4, j + 7, k + 10, Block.fence.blockID);
		world.setBlock(i + 4, j + 7, k + 14, Block.fence.blockID);
		world.setBlock(i + 4, j + 7, k + 15, Block.fence.blockID);
		world.setBlock(i + 4, j + 7, k + 19, Block.fence.blockID);
		world.setBlock(i + 4, j + 7, k + 20, Block.fence.blockID);
		world.setBlock(i + 4, j + 8, k + 9, Block.fence.blockID);
		world.setBlock(i + 4, j + 8, k + 10, Block.fence.blockID);
		world.setBlock(i + 4, j + 8, k + 14, Block.fence.blockID);
		world.setBlock(i + 4, j + 8, k + 15, Block.fence.blockID);
		world.setBlock(i + 4, j + 8, k + 19, Block.fence.blockID);
		world.setBlock(i + 4, j + 8, k + 20, Block.fence.blockID);
		world.setBlock(i + 4, j + 9, k + 10, Block.cloth.blockID);
		world.setBlock(i + 4, j + 9, k + 14, Block.cloth.blockID);
		world.setBlock(i + 4, j + 9, k + 15, Block.cloth.blockID);
		world.setBlock(i + 4, j + 10, k + 14, Block.cloth.blockID);
		world.setBlock(i + 4, j + 10, k + 15, Block.cloth.blockID);
		world.setBlock(i + 4, j + 11, k + 9, Block.cloth.blockID);
		world.setBlock(i + 4, j + 11, k + 10, Block.cloth.blockID);
		world.setBlock(i + 4, j + 11, k + 14, Block.cloth.blockID);
		world.setBlock(i + 4, j + 11, k + 15, Block.cloth.blockID);
		world.setBlock(i + 4, j + 11, k + 19, Block.cloth.blockID);
		world.setBlock(i + 4, j + 11, k + 20, Block.cloth.blockID);
		world.setBlock(i + 4, j + 12, k + 14, Block.cloth.blockID);
		world.setBlock(i + 4, j + 12, k + 15, Block.cloth.blockID);
		world.setBlock(i + 5, j + 3, k + 14, Block.cloth.blockID);
		world.setBlock(i + 5, j + 3, k + 15, Block.cloth.blockID);
		world.setBlock(i + 5, j + 4, k + 9, Block.cloth.blockID);
		world.setBlock(i + 5, j + 4, k + 10, Block.cloth.blockID);
		world.setBlock(i + 5, j + 4, k + 14, Block.cloth.blockID);
		world.setBlock(i + 5, j + 4, k + 15, Block.cloth.blockID);
		world.setBlock(i + 5, j + 5, k + 9, Block.cloth.blockID);
		world.setBlock(i + 5, j + 5, k + 10, Block.cloth.blockID);
		world.setBlock(i + 5, j + 5, k + 14, Block.cloth.blockID);
		world.setBlock(i + 5, j + 5, k + 15, Block.cloth.blockID);
		world.setBlock(i + 5, j + 6, k + 9, Block.cloth.blockID);
		world.setBlock(i + 5, j + 6, k + 10, Block.cloth.blockID);
		world.setBlock(i + 5, j + 6, k + 14, Block.cloth.blockID);
		world.setBlock(i + 5, j + 6, k + 15, Block.cloth.blockID);
		world.setBlock(i + 5, j + 6, k + 19, Block.cloth.blockID);
		world.setBlock(i + 5, j + 6, k + 20, Block.cloth.blockID);
		world.setBlock(i + 5, j + 7, k + 9, Block.fence.blockID);
		world.setBlock(i + 5, j + 7, k + 10, Block.fence.blockID);
		world.setBlock(i + 5, j + 7, k + 14, Block.fence.blockID);
		world.setBlock(i + 5, j + 7, k + 15, Block.fence.blockID);
		world.setBlock(i + 5, j + 7, k + 19, Block.fence.blockID);
		world.setBlock(i + 5, j + 7, k + 20, Block.fence.blockID);
		world.setBlock(i + 5, j + 8, k + 9, Block.fence.blockID);
		world.setBlock(i + 5, j + 8, k + 10, Block.fence.blockID);
		world.setBlock(i + 5, j + 8, k + 14, Block.fence.blockID);
		world.setBlock(i + 5, j + 8, k + 15, Block.fence.blockID);
		world.setBlock(i + 5, j + 8, k + 19, Block.fence.blockID);
		world.setBlock(i + 5, j + 8, k + 20, Block.fence.blockID);
		world.setBlock(i + 5, j + 9, k + 9, Block.cloth.blockID);
		world.setBlock(i + 5, j + 9, k + 10, Block.cloth.blockID);
		world.setBlock(i + 5, j + 9, k + 14, Block.cloth.blockID);
		world.setBlock(i + 5, j + 9, k + 19, Block.cloth.blockID);
		world.setBlock(i + 5, j + 9, k + 20, Block.cloth.blockID);
		world.setBlock(i + 5, j + 10, k + 15, Block.cloth.blockID);
		world.setBlock(i + 5, j + 10, k + 19, Block.cloth.blockID);
		world.setBlock(i + 5, j + 11, k + 9, Block.cloth.blockID);
		world.setBlock(i + 5, j + 11, k + 10, Block.cloth.blockID);
		world.setBlock(i + 5, j + 11, k + 14, Block.cloth.blockID);
		world.setBlock(i + 5, j + 11, k + 15, Block.cloth.blockID);
		world.setBlock(i + 5, j + 11, k + 19, Block.cloth.blockID);
		world.setBlock(i + 5, j + 11, k + 20, Block.cloth.blockID);
		world.setBlock(i + 5, j + 12, k + 14, Block.cloth.blockID);
		world.setBlock(i + 5, j + 12, k + 15, Block.cloth.blockID);
		world.setBlock(i + 6, j + 3, k + 14, Block.cloth.blockID);
		world.setBlock(i + 6, j + 3, k + 15, Block.cloth.blockID);
		world.setBlock(i + 6, j + 4, k + 9, Block.cloth.blockID);
		world.setBlock(i + 6, j + 4, k + 10, Block.cloth.blockID);
		world.setBlock(i + 6, j + 4, k + 15, Block.cloth.blockID);
		world.setBlock(i + 6, j + 4, k + 19, Block.cloth.blockID);
		world.setBlock(i + 6, j + 4, k + 20, Block.cloth.blockID);
		world.setBlock(i + 6, j + 5, k + 15, Block.cloth.blockID);
		world.setBlock(i + 6, j + 6, k + 9, Block.cloth.blockID);
		world.setBlock(i + 6, j + 6, k + 10, Block.cloth.blockID);
		world.setBlock(i + 6, j + 6, k + 14, Block.cloth.blockID);
		world.setBlock(i + 6, j + 6, k + 15, Block.cloth.blockID);
		world.setBlock(i + 6, j + 6, k + 19, Block.cloth.blockID);
		world.setBlock(i + 6, j + 6, k + 20, Block.cloth.blockID);
		world.setBlock(i + 6, j + 7, k + 9, Block.fence.blockID);
		world.setBlock(i + 6, j + 7, k + 10, Block.fence.blockID);
		world.setBlock(i + 6, j + 7, k + 14, Block.fence.blockID);
		world.setBlock(i + 6, j + 7, k + 15, Block.fence.blockID);
		world.setBlock(i + 6, j + 7, k + 19, Block.fence.blockID);
		world.setBlock(i + 6, j + 7, k + 20, Block.fence.blockID);
		world.setBlock(i + 6, j + 8, k + 9, Block.fence.blockID);
		world.setBlock(i + 6, j + 8, k + 10, Block.fence.blockID);
		world.setBlock(i + 6, j + 8, k + 14, Block.fence.blockID);
		world.setBlock(i + 6, j + 8, k + 15, Block.fence.blockID);
		world.setBlock(i + 6, j + 8, k + 19, Block.fence.blockID);
		world.setBlock(i + 6, j + 8, k + 20, Block.fence.blockID);
		world.setBlock(i + 6, j + 9, k + 9, Block.cloth.blockID);
		world.setBlock(i + 6, j + 9, k + 10, Block.cloth.blockID);
		world.setBlock(i + 6, j + 9, k + 14, Block.cloth.blockID);
		world.setBlock(i + 6, j + 9, k + 19, Block.cloth.blockID);
		world.setBlock(i + 6, j + 9, k + 20, Block.cloth.blockID);
		world.setBlock(i + 6, j + 10, k + 9, Block.cloth.blockID);
		world.setBlock(i + 6, j + 10, k + 10, Block.cloth.blockID);
		world.setBlock(i + 6, j + 10, k + 15, Block.cloth.blockID);
		world.setBlock(i + 6, j + 10, k + 19, Block.cloth.blockID);
		world.setBlock(i + 6, j + 10, k + 20, Block.cloth.blockID);
		world.setBlock(i + 6, j + 11, k + 9, Block.cloth.blockID);
		world.setBlock(i + 6, j + 11, k + 10, Block.cloth.blockID);
		world.setBlock(i + 6, j + 11, k + 14, Block.cloth.blockID);
		world.setBlock(i + 6, j + 11, k + 15, Block.cloth.blockID);
		world.setBlock(i + 6, j + 11, k + 19, Block.cloth.blockID);
		world.setBlock(i + 6, j + 11, k + 20, Block.cloth.blockID);
		world.setBlock(i + 6, j + 12, k + 14, Block.cloth.blockID);
		world.setBlock(i + 6, j + 12, k + 15, Block.cloth.blockID);
		world.setBlock(i + 7, j + 3, k + 14, Block.cloth.blockID);
		world.setBlock(i + 7, j + 3, k + 15, Block.cloth.blockID);
		world.setBlock(i + 7, j + 4, k + 14, Block.cloth.blockID);
		world.setBlock(i + 7, j + 4, k + 15, Block.cloth.blockID);
		world.setBlock(i + 7, j + 4, k + 19, Block.cloth.blockID);
		world.setBlock(i + 7, j + 4, k + 20, Block.cloth.blockID);
		world.setBlock(i + 7, j + 5, k + 14, Block.cloth.blockID);
		world.setBlock(i + 7, j + 5, k + 15, Block.cloth.blockID);
		world.setBlock(i + 7, j + 5, k + 19, Block.cloth.blockID);
		world.setBlock(i + 7, j + 5, k + 20, Block.cloth.blockID);
		world.setBlock(i + 7, j + 6, k + 9, Block.cloth.blockID);
		world.setBlock(i + 7, j + 6, k + 10, Block.cloth.blockID);
		world.setBlock(i + 7, j + 6, k + 14, Block.cloth.blockID);
		world.setBlock(i + 7, j + 6, k + 15, Block.cloth.blockID);
		world.setBlock(i + 7, j + 6, k + 19, Block.cloth.blockID);
		world.setBlock(i + 7, j + 6, k + 20, Block.cloth.blockID);
		world.setBlock(i + 7, j + 7, k + 9, Block.fence.blockID);
		world.setBlock(i + 7, j + 7, k + 10, Block.fence.blockID);
		world.setBlock(i + 7, j + 7, k + 14, Block.fence.blockID);
		world.setBlock(i + 7, j + 7, k + 15, Block.fence.blockID);
		world.setBlock(i + 7, j + 7, k + 19, Block.fence.blockID);
		world.setBlock(i + 7, j + 7, k + 20, Block.fence.blockID);
		world.setBlock(i + 7, j + 8, k + 9, Block.fence.blockID);
		world.setBlock(i + 7, j + 8, k + 10, Block.fence.blockID);
		world.setBlock(i + 7, j + 8, k + 14, Block.fence.blockID);
		world.setBlock(i + 7, j + 8, k + 15, Block.fence.blockID);
		world.setBlock(i + 7, j + 8, k + 19, Block.fence.blockID);
		world.setBlock(i + 7, j + 8, k + 20, Block.fence.blockID);
		world.setBlock(i + 7, j + 9, k + 9, Block.cloth.blockID);
		world.setBlock(i + 7, j + 9, k + 10, Block.cloth.blockID);
		world.setBlock(i + 7, j + 9, k + 14, Block.cloth.blockID);
		world.setBlock(i + 7, j + 9, k + 15, Block.cloth.blockID);
		world.setBlock(i + 7, j + 9, k + 19, Block.cloth.blockID);
		world.setBlock(i + 7, j + 9, k + 20, Block.cloth.blockID);
		world.setBlock(i + 7, j + 10, k + 9, Block.cloth.blockID);
		world.setBlock(i + 7, j + 10, k + 14, Block.cloth.blockID);
		world.setBlock(i + 7, j + 10, k + 15, Block.cloth.blockID);
		world.setBlock(i + 7, j + 10, k + 19, Block.cloth.blockID);
		world.setBlock(i + 7, j + 11, k + 9, Block.cloth.blockID);
		world.setBlock(i + 7, j + 11, k + 10, Block.cloth.blockID);
		world.setBlock(i + 7, j + 11, k + 14, Block.cloth.blockID);
		world.setBlock(i + 7, j + 11, k + 15, Block.cloth.blockID);
		world.setBlock(i + 7, j + 11, k + 19, Block.cloth.blockID);
		world.setBlock(i + 7, j + 11, k + 20, Block.cloth.blockID);
		world.setBlock(i + 7, j + 12, k + 14, Block.cloth.blockID);
		world.setBlock(i + 7, j + 12, k + 15, Block.cloth.blockID);
		world.setBlock(i + 8, j + 3, k + 14, Block.cloth.blockID);
		world.setBlock(i + 8, j + 3, k + 15, Block.cloth.blockID);
		world.setBlock(i + 8, j + 4, k + 9, Block.cloth.blockID);
		world.setBlock(i + 8, j + 4, k + 10, Block.cloth.blockID);
		world.setBlock(i + 8, j + 4, k + 14, Block.cloth.blockID);
		world.setBlock(i + 8, j + 4, k + 15, Block.cloth.blockID);
		world.setBlock(i + 8, j + 4, k + 19, Block.cloth.blockID);
		world.setBlock(i + 8, j + 4, k + 20, Block.cloth.blockID);
		world.setBlock(i + 8, j + 5, k + 9, Block.cloth.blockID);
		world.setBlock(i + 8, j + 5, k + 10, Block.cloth.blockID);
		world.setBlock(i + 8, j + 5, k + 14, Block.cloth.blockID);
		world.setBlock(i + 8, j + 5, k + 15, Block.cloth.blockID);
		world.setBlock(i + 8, j + 5, k + 19, Block.cloth.blockID);
		world.setBlock(i + 8, j + 5, k + 20, Block.cloth.blockID);
		world.setBlock(i + 8, j + 6, k + 9, Block.cloth.blockID);
		world.setBlock(i + 8, j + 6, k + 10, Block.cloth.blockID);
		world.setBlock(i + 8, j + 6, k + 14, Block.cloth.blockID);
		world.setBlock(i + 8, j + 6, k + 15, Block.cloth.blockID);
		world.setBlock(i + 8, j + 6, k + 19, Block.cloth.blockID);
		world.setBlock(i + 8, j + 6, k + 20, Block.cloth.blockID);
		world.setBlock(i + 8, j + 7, k + 9, Block.fence.blockID);
		world.setBlock(i + 8, j + 7, k + 10, Block.fence.blockID);
		world.setBlock(i + 8, j + 7, k + 14, Block.fence.blockID);
		world.setBlock(i + 8, j + 7, k + 15, Block.fence.blockID);
		world.setBlock(i + 8, j + 7, k + 19, Block.fence.blockID);
		world.setBlock(i + 8, j + 7, k + 20, Block.fence.blockID);
		world.setBlock(i + 8, j + 8, k + 9, Block.fence.blockID);
		world.setBlock(i + 8, j + 8, k + 10, Block.fence.blockID);
		world.setBlock(i + 8, j + 8, k + 14, Block.fence.blockID);
		world.setBlock(i + 8, j + 8, k + 15, Block.fence.blockID);
		world.setBlock(i + 8, j + 8, k + 19, Block.fence.blockID);
		world.setBlock(i + 8, j + 8, k + 20, Block.fence.blockID);
		world.setBlock(i + 8, j + 9, k + 9, Block.cloth.blockID);
		world.setBlock(i + 8, j + 9, k + 10, Block.cloth.blockID);
		world.setBlock(i + 8, j + 9, k + 14, Block.cloth.blockID);
		world.setBlock(i + 8, j + 9, k + 15, Block.cloth.blockID);
		world.setBlock(i + 8, j + 9, k + 19, Block.cloth.blockID);
		world.setBlock(i + 8, j + 9, k + 20, Block.cloth.blockID);
		world.setBlock(i + 8, j + 10, k + 9, Block.cloth.blockID);
		world.setBlock(i + 8, j + 10, k + 10, Block.cloth.blockID);
		world.setBlock(i + 8, j + 10, k + 14, Block.cloth.blockID);
		world.setBlock(i + 8, j + 10, k + 15, Block.cloth.blockID);
		world.setBlock(i + 8, j + 10, k + 19, Block.cloth.blockID);
		world.setBlock(i + 8, j + 10, k + 20, Block.cloth.blockID);
		world.setBlock(i + 8, j + 11, k + 9, Block.cloth.blockID);
		world.setBlock(i + 8, j + 11, k + 10, Block.cloth.blockID);
		world.setBlock(i + 8, j + 11, k + 14, Block.cloth.blockID);
		world.setBlock(i + 8, j + 11, k + 15, Block.cloth.blockID);
		world.setBlock(i + 8, j + 11, k + 19, Block.cloth.blockID);
		world.setBlock(i + 8, j + 11, k + 20, Block.cloth.blockID);
		world.setBlock(i + 8, j + 12, k + 14, Block.cloth.blockID);
		world.setBlock(i + 8, j + 12, k + 15, Block.cloth.blockID);
		world.setBlock(i + 9, j + 3, k + 14, Block.fence.blockID);
		world.setBlock(i + 9, j + 3, k + 15, Block.fence.blockID);
		world.setBlock(i + 9, j + 4, k + 9, Block.fence.blockID);
		world.setBlock(i + 9, j + 4, k + 10, Block.fence.blockID);
		world.setBlock(i + 9, j + 4, k + 14, Block.fence.blockID);
		world.setBlock(i + 9, j + 4, k + 15, Block.fence.blockID);
		world.setBlock(i + 9, j + 4, k + 19, Block.fence.blockID);
		world.setBlock(i + 9, j + 4, k + 20, Block.fence.blockID);
		world.setBlock(i + 9, j + 5, k + 9, Block.fence.blockID);
		world.setBlock(i + 9, j + 5, k + 10, Block.fence.blockID);
		world.setBlock(i + 9, j + 5, k + 14, Block.fence.blockID);
		world.setBlock(i + 9, j + 5, k + 15, Block.fence.blockID);
		world.setBlock(i + 9, j + 5, k + 19, Block.fence.blockID);
		world.setBlock(i + 9, j + 5, k + 20, Block.fence.blockID);
		world.setBlock(i + 9, j + 6, k + 9, Block.fence.blockID);
		world.setBlock(i + 9, j + 6, k + 10, Block.fence.blockID);
		world.setBlock(i + 9, j + 6, k + 14, Block.fence.blockID);
		world.setBlock(i + 9, j + 6, k + 15, Block.fence.blockID);
		world.setBlock(i + 9, j + 6, k + 19, Block.fence.blockID);
		world.setBlock(i + 9, j + 6, k + 20, Block.fence.blockID);
		world.setBlock(i + 9, j + 7, k + 9, Block.fence.blockID);
		world.setBlock(i + 9, j + 7, k + 10, Block.fence.blockID);
		world.setBlock(i + 9, j + 7, k + 14, Block.fence.blockID);
		world.setBlock(i + 9, j + 7, k + 15, Block.fence.blockID);
		world.setBlock(i + 9, j + 7, k + 19, Block.fence.blockID);
		world.setBlock(i + 9, j + 7, k + 20, Block.fence.blockID);
		world.setBlock(i + 9, j + 8, k + 9, Block.fence.blockID);
		world.setBlock(i + 9, j + 8, k + 10, Block.fence.blockID);
		world.setBlock(i + 9, j + 8, k + 14, Block.fence.blockID);
		world.setBlock(i + 9, j + 8, k + 15, Block.fence.blockID);
		world.setBlock(i + 9, j + 8, k + 19, Block.fence.blockID);
		world.setBlock(i + 9, j + 8, k + 20, Block.fence.blockID);
		world.setBlock(i + 9, j + 9, k + 9, Block.fence.blockID);
		world.setBlock(i + 9, j + 9, k + 10, Block.fence.blockID);
		world.setBlock(i + 9, j + 9, k + 14, Block.fence.blockID);
		world.setBlock(i + 9, j + 9, k + 15, Block.fence.blockID);
		world.setBlock(i + 9, j + 9, k + 19, Block.fence.blockID);
		world.setBlock(i + 9, j + 9, k + 20, Block.fence.blockID);
		world.setBlock(i + 9, j + 10, k + 9, Block.fence.blockID);
		world.setBlock(i + 9, j + 10, k + 10, Block.fence.blockID);
		world.setBlock(i + 9, j + 10, k + 14, Block.fence.blockID);
		world.setBlock(i + 9, j + 10, k + 15, Block.fence.blockID);
		world.setBlock(i + 9, j + 10, k + 19, Block.fence.blockID);
		world.setBlock(i + 9, j + 10, k + 20, Block.fence.blockID);
		world.setBlock(i + 9, j + 11, k + 9, Block.fence.blockID);
		world.setBlock(i + 9, j + 11, k + 10, Block.fence.blockID);
		world.setBlock(i + 9, j + 11, k + 14, Block.fence.blockID);
		world.setBlock(i + 9, j + 11, k + 15, Block.fence.blockID);
		world.setBlock(i + 9, j + 11, k + 19, Block.fence.blockID);
		world.setBlock(i + 9, j + 11, k + 20, Block.fence.blockID);
		world.setBlock(i + 9, j + 12, k + 14, Block.fence.blockID);
		world.setBlock(i + 9, j + 12, k + 15, Block.fence.blockID);
		world.setBlock(i + 10, j + 7, k + 9, Block.fence.blockID);
		world.setBlock(i + 10, j + 7, k + 10, Block.fence.blockID);
		world.setBlock(i + 10, j + 7, k + 14, Block.fence.blockID);
		world.setBlock(i + 10, j + 7, k + 15, Block.fence.blockID);
		world.setBlock(i + 10, j + 7, k + 19, Block.fence.blockID);
		world.setBlock(i + 10, j + 7, k + 20, Block.fence.blockID);
		world.setBlock(i + 10, j + 8, k + 9, Block.fence.blockID);
		world.setBlock(i + 10, j + 8, k + 10, Block.fence.blockID);
		world.setBlock(i + 10, j + 8, k + 14, Block.fence.blockID);
		world.setBlock(i + 10, j + 8, k + 15, Block.fence.blockID);
		world.setBlock(i + 10, j + 8, k + 19, Block.fence.blockID);
		world.setBlock(i + 10, j + 8, k + 20, Block.fence.blockID);
		world.setBlock(i + 11, j + 4, k + 28, Block.cloth.blockID, 5, 2);
		world.setBlock(i + 11, j + 7, k + 9, Block.fence.blockID);
		world.setBlock(i + 11, j + 7, k + 10, Block.fence.blockID);
		world.setBlock(i + 11, j + 7, k + 14, Block.fence.blockID);
		world.setBlock(i + 11, j + 7, k + 15, Block.fence.blockID);
		world.setBlock(i + 11, j + 7, k + 19, Block.fence.blockID);
		world.setBlock(i + 11, j + 7, k + 20, Block.fence.blockID);
		world.setBlock(i + 11, j + 8, k + 9, Block.fence.blockID);
		world.setBlock(i + 11, j + 8, k + 10, Block.fence.blockID);
		world.setBlock(i + 11, j + 8, k + 14, Block.fence.blockID);
		world.setBlock(i + 11, j + 8, k + 15, Block.fence.blockID);
		world.setBlock(i + 11, j + 8, k + 19, Block.fence.blockID);
		world.setBlock(i + 11, j + 8, k + 20, Block.fence.blockID);
		world.setBlock(i + 11, j + 13, k + 9, Block.cloth.blockID, 5, 2);
		world.setBlock(i + 11, j + 14, k + 9, Block.cloth.blockID, 5, 2);
		world.setBlock(i + 12, j + 2, k + 8, Block.planks.blockID, 1, 2);
		world.setBlock(i + 12, j + 2, k + 9, Block.planks.blockID, 1, 2);
		world.setBlock(i + 12, j + 2, k + 10, Block.planks.blockID, 1, 2);
		world.setBlock(i + 12, j + 2, k + 11, Block.planks.blockID, 1, 2);
		world.setBlock(i + 12, j + 2, k + 12, Block.planks.blockID, 1, 2);
		world.setBlock(i + 12, j + 2, k + 13, Block.planks.blockID, 1, 2);
		world.setBlock(i + 12, j + 2, k + 14, Block.planks.blockID, 1, 2);
		world.setBlock(i + 12, j + 2, k + 15, Block.planks.blockID, 1, 2);
		world.setBlock(i + 12, j + 2, k + 16, Block.planks.blockID, 1, 2);
		world.setBlock(i + 12, j + 2, k + 17, Block.planks.blockID, 1, 2);
		world.setBlock(i + 12, j + 2, k + 18, Block.planks.blockID, 1, 2);
		world.setBlock(i + 12, j + 2, k + 19, Block.planks.blockID, 1, 2);
		world.setBlock(i + 12, j + 2, k + 20, Block.planks.blockID, 1, 2);
		world.setBlock(i + 12, j + 2, k + 21, Block.planks.blockID, 1, 2);
		world.setBlock(i + 12, j + 2, k + 22, Block.planks.blockID, 1, 2);
		world.setBlock(i + 12, j + 2, k + 23, Block.planks.blockID, 1, 2);
		world.setBlock(i + 12, j + 2, k + 28, Block.cloth.blockID, 5, 2);
		world.setBlock(i + 12, j + 3, k + 5, Block.planks.blockID, 1, 2);
		world.setBlock(i + 12, j + 3, k + 6, Block.planks.blockID, 1, 2);
		world.setBlock(i + 12, j + 3, k + 7, Block.planks.blockID, 1, 2);
		world.setBlock(i + 12, j + 3, k + 8, Block.planks.blockID, 1, 2);
		world.setBlock(i + 12, j + 3, k + 23, Block.planks.blockID, 1, 2);
		world.setBlock(i + 12, j + 3, k + 24, Block.planks.blockID, 1, 2);
		world.setBlock(i + 12, j + 3, k + 25, Block.planks.blockID, 1, 2);
		world.setBlock(i + 12, j + 3, k + 26, Block.planks.blockID, 1, 2);
		world.setBlock(i + 12, j + 3, k + 27, Block.cloth.blockID, 5, 2);
		world.setBlock(i + 12, j + 3, k + 28, Block.cloth.blockID, 5, 2);
		world.setBlock(i + 12, j + 4, k + 3, Block.planks.blockID, 1, 2);
		world.setBlock(i + 12, j + 4, k + 4, Block.planks.blockID, 1, 2);
		world.setBlock(i + 12, j + 4, k + 5, Block.planks.blockID, 1, 2);
		world.setBlock(i + 12, j + 4, k + 26, Block.planks.blockID, 1, 2);
		world.setBlock(i + 12, j + 4, k + 27, Block.planks.blockID, 1, 2);
		world.setBlock(i + 12, j + 4, k + 28, Block.planks.blockID, 1, 2);
		world.setBlock(i + 12, j + 4, k + 29, Block.planks.blockID, 1, 2);
		world.setBlock(i + 12, j + 5, k + 3, Block.planks.blockID, 1, 2);
		world.setBlock(i + 12, j + 5, k + 29, Block.planks.blockID, 1, 2);
		world.setBlock(i + 12, j + 5, k + 30, Block.planks.blockID, 1, 2);
		world.setBlock(i + 12, j + 5, k + 31, Block.planks.blockID, 1, 2);
		world.setBlock(i + 12, j + 6, k + 2, Block.planks.blockID, 1, 2);
		world.setBlock(i + 12, j + 6, k + 3, Block.planks.blockID, 1, 2);
		world.setBlock(i + 12, j + 6, k + 31, Block.planks.blockID, 1, 2);
		world.setBlock(i + 12, j + 6, k + 32, Block.planks.blockID, 1, 2);
		world.setBlock(i + 12, j + 7, k + 2, Block.planks.blockID, 1, 2);
		world.setBlock(i + 12, j + 7, k + 9, Block.fence.blockID);
		world.setBlock(i + 12, j + 7, k + 10, Block.fence.blockID);
		world.setBlock(i + 12, j + 7, k + 14, Block.fence.blockID);
		world.setBlock(i + 12, j + 7, k + 15, Block.fence.blockID);
		world.setBlock(i + 12, j + 7, k + 19, Block.fence.blockID);
		world.setBlock(i + 12, j + 7, k + 20, Block.fence.blockID);
		world.setBlock(i + 12, j + 7, k + 32, Block.planks.blockID, 1, 2);
		world.setBlock(i + 12, j + 8, k + 2, Block.planks.blockID, 1, 2);
		world.setBlock(i + 12, j + 8, k + 9, Block.fence.blockID);
		world.setBlock(i + 12, j + 8, k + 10, Block.fence.blockID);
		world.setBlock(i + 12, j + 8, k + 14, Block.fence.blockID);
		world.setBlock(i + 12, j + 8, k + 15, Block.fence.blockID);
		world.setBlock(i + 12, j + 8, k + 19, Block.fence.blockID);
		world.setBlock(i + 12, j + 8, k + 20, Block.fence.blockID);
		world.setBlock(i + 12, j + 8, k + 32, Block.planks.blockID, 1, 2);
		world.setBlock(i + 12, j + 9, k + 2, Block.planks.blockID, 1, 2);
		world.setBlock(i + 12, j + 9, k + 3, Block.planks.blockID, 1, 2);
		world.setBlock(i + 12, j + 9, k + 31, Block.planks.blockID, 1, 2);
		world.setBlock(i + 12, j + 9, k + 32, Block.planks.blockID, 1, 2);
		world.setBlock(i + 12, j + 10, k + 3, Block.planks.blockID, 1, 2);
		world.setBlock(i + 12, j + 10, k + 29, Block.planks.blockID, 1, 2);
		world.setBlock(i + 12, j + 10, k + 30, Block.planks.blockID, 1, 2);
		world.setBlock(i + 12, j + 10, k + 31, Block.planks.blockID, 1, 2);
		world.setBlock(i + 12, j + 11, k + 3, Block.planks.blockID, 1, 2);
		world.setBlock(i + 12, j + 11, k + 4, Block.planks.blockID, 1, 2);
		world.setBlock(i + 12, j + 11, k + 5, Block.planks.blockID, 1, 2);
		world.setBlock(i + 12, j + 11, k + 26, Block.planks.blockID, 1, 2);
		world.setBlock(i + 12, j + 11, k + 27, Block.planks.blockID, 1, 2);
		world.setBlock(i + 12, j + 11, k + 28, Block.planks.blockID, 1, 2);
		world.setBlock(i + 12, j + 11, k + 29, Block.planks.blockID, 1, 2);
		world.setBlock(i + 12, j + 12, k + 5, Block.planks.blockID, 1, 2);
		world.setBlock(i + 12, j + 12, k + 6, Block.planks.blockID, 1, 2);
		world.setBlock(i + 12, j + 12, k + 7, Block.planks.blockID, 1, 2);
		world.setBlock(i + 12, j + 12, k + 8, Block.planks.blockID, 1, 2);
		world.setBlock(i + 12, j + 12, k + 23, Block.planks.blockID, 1, 2);
		world.setBlock(i + 12, j + 12, k + 24, Block.planks.blockID, 1, 2);
		world.setBlock(i + 12, j + 12, k + 25, Block.planks.blockID, 1, 2);
		world.setBlock(i + 12, j + 12, k + 26, Block.planks.blockID, 1, 2);
		world.setBlock(i + 12, j + 13, k + 8, Block.planks.blockID, 1, 2);
		world.setBlock(i + 12, j + 13, k + 9, Block.planks.blockID, 1, 2);
		world.setBlock(i + 12, j + 13, k + 10, Block.planks.blockID, 1, 2);
		world.setBlock(i + 12, j + 13, k + 11, Block.planks.blockID, 1, 2);
		world.setBlock(i + 12, j + 13, k + 12, Block.planks.blockID, 1, 2);
		world.setBlock(i + 12, j + 13, k + 13, Block.planks.blockID, 1, 2);
		world.setBlock(i + 12, j + 13, k + 14, Block.planks.blockID, 1, 2);
		world.setBlock(i + 12, j + 13, k + 15, Block.planks.blockID, 1, 2);
		world.setBlock(i + 12, j + 13, k + 16, Block.planks.blockID, 1, 2);
		world.setBlock(i + 12, j + 13, k + 17, Block.planks.blockID, 1, 2);
		world.setBlock(i + 12, j + 13, k + 18, Block.planks.blockID, 1, 2);
		world.setBlock(i + 12, j + 13, k + 19, Block.planks.blockID, 1, 2);
		world.setBlock(i + 12, j + 13, k + 20, Block.planks.blockID, 1, 2);
		world.setBlock(i + 12, j + 13, k + 21, Block.planks.blockID, 1, 2);
		world.setBlock(i + 12, j + 13, k + 22, Block.planks.blockID, 1, 2);
		world.setBlock(i + 12, j + 13, k + 23, Block.planks.blockID, 1, 2);
		world.setBlock(i + 12, j + 14, k + 9, Block.cloth.blockID, 5, 2);
		world.setBlock(i + 12, j + 14, k + 10, Block.cloth.blockID, 5, 2);
		world.setBlock(i + 13, j + 2, k + 8, Block.planks.blockID, 1, 2);
		world.setBlock(i + 13, j + 2, k + 9, Block.planks.blockID, 1, 2);
		world.setBlock(i + 13, j + 2, k + 10, Block.planks.blockID, 1, 2);
		world.setBlock(i + 13, j + 2, k + 11, Block.planks.blockID, 1, 2);
		world.setBlock(i + 13, j + 2, k + 12, Block.planks.blockID, 1, 2);
		world.setBlock(i + 13, j + 2, k + 13, Block.planks.blockID, 1, 2);
		world.setBlock(i + 13, j + 2, k + 14, Block.planks.blockID, 1, 2);
		world.setBlock(i + 13, j + 2, k + 15, Block.planks.blockID, 1, 2);
		world.setBlock(i + 13, j + 2, k + 16, Block.planks.blockID, 1, 2);
		world.setBlock(i + 13, j + 2, k + 17, Block.planks.blockID, 1, 2);
		world.setBlock(i + 13, j + 2, k + 18, Block.planks.blockID, 1, 2);
		world.setBlock(i + 13, j + 2, k + 19, Block.planks.blockID, 1, 2);
		world.setBlock(i + 13, j + 2, k + 20, Block.planks.blockID, 1, 2);
		world.setBlock(i + 13, j + 2, k + 21, Block.planks.blockID, 1, 2);
		world.setBlock(i + 13, j + 2, k + 22, Block.planks.blockID, 1, 2);
		world.setBlock(i + 13, j + 2, k + 23, Block.planks.blockID, 1, 2);
		world.setBlock(i + 13, j + 3, k + 5, Block.planks.blockID, 1, 2);
		world.setBlock(i + 13, j + 3, k + 6, Block.planks.blockID, 1, 2);
		world.setBlock(i + 13, j + 3, k + 7, Block.planks.blockID, 1, 2);
		world.setBlock(i + 13, j + 3, k + 8, Block.planks.blockID, 1, 2);
		world.setBlock(i + 13, j + 3, k + 9, Block.planks.blockID, 1, 2);
		world.setBlock(i + 13, j + 3, k + 10, Block.planks.blockID, 1, 2);
		world.setBlock(i + 13, j + 3, k + 11, Block.planks.blockID, 1, 2);
		world.setBlock(i + 13, j + 3, k + 12, Block.planks.blockID, 1, 2);
		world.setBlock(i + 13, j + 3, k + 13, Block.planks.blockID, 1, 2);
		world.setBlock(i + 13, j + 3, k + 14, Block.planks.blockID, 1, 2);
		world.setBlock(i + 13, j + 3, k + 15, Block.planks.blockID, 1, 2);
		world.setBlock(i + 13, j + 3, k + 16, Block.planks.blockID, 1, 2);
		world.setBlock(i + 13, j + 3, k + 17, Block.planks.blockID, 1, 2);
		world.setBlock(i + 13, j + 3, k + 18, Block.planks.blockID, 1, 2);
		world.setBlock(i + 13, j + 3, k + 19, Block.planks.blockID, 1, 2);
		world.setBlock(i + 13, j + 3, k + 20, Block.planks.blockID, 1, 2);
		world.setBlock(i + 13, j + 3, k + 21, Block.planks.blockID, 1, 2);
		world.setBlock(i + 13, j + 3, k + 22, Block.planks.blockID, 1, 2);
		world.setBlock(i + 13, j + 3, k + 23, Block.planks.blockID, 1, 2);
		world.setBlock(i + 13, j + 3, k + 24, Block.planks.blockID, 1, 2);
		world.setBlock(i + 13, j + 3, k + 25, Block.planks.blockID, 1, 2);
		world.setBlock(i + 13, j + 3, k + 26, Block.planks.blockID, 1, 2);
		world.setBlock(i + 13, j + 3, k + 27, Block.cloth.blockID, 5, 2);
		world.setBlock(i + 13, j + 4, k + 3, Block.planks.blockID, 1, 2);
		world.setBlock(i + 13, j + 4, k + 4, Block.planks.blockID, 1, 2);
		world.setBlock(i + 13, j + 4, k + 5, Block.planks.blockID, 1, 2);
		world.setBlock(i + 13, j + 4, k + 6, Block.planks.blockID, 1, 2);
		world.setBlock(i + 13, j + 4, k + 7, Block.planks.blockID, 1, 2);
		world.setBlock(i + 13, j + 4, k + 8, Block.planks.blockID, 1, 2);
		world.setBlock(i + 13, j + 4, k + 9, Block.planks.blockID, 1, 2);
		world.setBlock(i + 13, j + 4, k + 10, Block.planks.blockID, 1, 2);
		world.setBlock(i + 13, j + 4, k + 11, Block.planks.blockID, 1, 2);
		world.setBlock(i + 13, j + 4, k + 12, Block.planks.blockID, 1, 2);
		world.setBlock(i + 13, j + 4, k + 13, Block.planks.blockID, 1, 2);
		world.setBlock(i + 13, j + 4, k + 14, Block.planks.blockID, 1, 2);
		world.setBlock(i + 13, j + 4, k + 15, Block.planks.blockID, 1, 2);
		world.setBlock(i + 13, j + 4, k + 16, Block.planks.blockID, 1, 2);
		world.setBlock(i + 13, j + 4, k + 17, Block.planks.blockID, 1, 2);
		world.setBlock(i + 13, j + 4, k + 18, Block.planks.blockID, 1, 2);
		world.setBlock(i + 13, j + 4, k + 19, Block.planks.blockID, 1, 2);
		world.setBlock(i + 13, j + 4, k + 20, Block.planks.blockID, 1, 2);
		world.setBlock(i + 13, j + 4, k + 21, Block.planks.blockID, 1, 2);
		world.setBlock(i + 13, j + 4, k + 22, Block.planks.blockID, 1, 2);
		world.setBlock(i + 13, j + 4, k + 23, Block.planks.blockID, 1, 2);
		world.setBlock(i + 13, j + 4, k + 24, Block.planks.blockID, 1, 2);
		world.setBlock(i + 13, j + 4, k + 25, Block.planks.blockID, 1, 2);
		world.setBlock(i + 13, j + 4, k + 26, Block.planks.blockID, 1, 2);
		world.setBlock(i + 13, j + 4, k + 27, Block.planks.blockID, 1, 2);
		world.setBlock(i + 13, j + 4, k + 28, Block.planks.blockID, 1, 2);
		world.setBlock(i + 13, j + 4, k + 29, Block.planks.blockID, 1, 2);
		world.setBlock(i + 13, j + 5, k + 3, Block.planks.blockID, 1, 2);
		world.setBlock(i + 13, j + 5, k + 4, Block.planks.blockID, 1, 2);
		world.setBlock(i + 13, j + 5, k + 5, Block.planks.blockID, 1, 2);
		world.setBlock(i + 13, j + 5, k + 6, Block.planks.blockID, 1, 2);
		world.setBlock(i + 13, j + 5, k + 7, Block.planks.blockID, 1, 2);
		world.setBlock(i + 13, j + 5, k + 8, Block.planks.blockID, 1, 2);
		world.setBlock(i + 13, j + 5, k + 9, Block.planks.blockID, 1, 2);
		world.setBlock(i + 13, j + 5, k + 10, Block.planks.blockID, 1, 2);
		world.setBlock(i + 13, j + 5, k + 11, Block.planks.blockID, 1, 2);
		world.setBlock(i + 13, j + 5, k + 12, Block.planks.blockID, 1, 2);
		world.setBlock(i + 13, j + 5, k + 13, Block.planks.blockID, 1, 2);
		world.setBlock(i + 13, j + 5, k + 14, Block.planks.blockID, 1, 2);
		world.setBlock(i + 13, j + 5, k + 15, Block.planks.blockID, 1, 2);
		world.setBlock(i + 13, j + 5, k + 16, Block.planks.blockID, 1, 2);
		world.setBlock(i + 13, j + 5, k + 17, Block.planks.blockID, 1, 2);
		world.setBlock(i + 13, j + 5, k + 18, Block.planks.blockID, 1, 2);
		world.setBlock(i + 13, j + 5, k + 19, Block.planks.blockID, 1, 2);
		world.setBlock(i + 13, j + 5, k + 20, Block.planks.blockID, 1, 2);
		world.setBlock(i + 13, j + 5, k + 21, Block.planks.blockID, 1, 2);
		world.setBlock(i + 13, j + 5, k + 22, Block.planks.blockID, 1, 2);
		world.setBlock(i + 13, j + 5, k + 23, Block.planks.blockID, 1, 2);
		world.setBlock(i + 13, j + 5, k + 24, Block.planks.blockID, 1, 2);
		world.setBlock(i + 13, j + 5, k + 25, Block.planks.blockID, 1, 2);
		world.setBlock(i + 13, j + 5, k + 26, Block.planks.blockID, 1, 2);
		world.setBlock(i + 13, j + 5, k + 27, Block.planks.blockID, 1, 2);
		world.setBlock(i + 13, j + 5, k + 28, Block.planks.blockID, 1, 2);
		world.setBlock(i + 13, j + 5, k + 29, Block.planks.blockID, 1, 2);
		world.setBlock(i + 13, j + 5, k + 30, Block.planks.blockID, 1, 2);
		world.setBlock(i + 13, j + 5, k + 31, Block.planks.blockID, 1, 2);
		world.setBlock(i + 13, j + 6, k + 2, Block.planks.blockID, 1, 2);
		world.setBlock(i + 13, j + 6, k + 3, Block.planks.blockID, 1, 2);
		world.setBlock(i + 13, j + 6, k + 4, Block.planks.blockID, 1, 2);
		world.setBlock(i + 13, j + 6, k + 5, Block.planks.blockID, 1, 2);
		world.setBlock(i + 13, j + 6, k + 6, Block.planks.blockID, 1, 2);
		world.setBlock(i + 13, j + 6, k + 7, Block.planks.blockID, 1, 2);
		world.setBlock(i + 13, j + 6, k + 8, Block.planks.blockID, 1, 2);
		world.setBlock(i + 13, j + 6, k + 9, Block.planks.blockID, 1, 2);
		world.setBlock(i + 13, j + 6, k + 10, Block.planks.blockID, 1, 2);
		world.setBlock(i + 13, j + 6, k + 11, Block.planks.blockID, 1, 2);
		world.setBlock(i + 13, j + 6, k + 12, Block.planks.blockID, 1, 2);
		world.setBlock(i + 13, j + 6, k + 13, Block.planks.blockID, 1, 2);
		world.setBlock(i + 13, j + 6, k + 14, Block.planks.blockID, 1, 2);
		world.setBlock(i + 13, j + 6, k + 15, Block.planks.blockID, 1, 2);
		world.setBlock(i + 13, j + 6, k + 16, Block.planks.blockID, 1, 2);
		world.setBlock(i + 13, j + 6, k + 17, Block.planks.blockID, 1, 2);
		world.setBlock(i + 13, j + 6, k + 18, Block.planks.blockID, 1, 2);
		world.setBlock(i + 13, j + 6, k + 19, Block.planks.blockID, 1, 2);
		world.setBlock(i + 13, j + 6, k + 20, Block.planks.blockID, 1, 2);
		world.setBlock(i + 13, j + 6, k + 21, Block.planks.blockID, 1, 2);
		world.setBlock(i + 13, j + 6, k + 22, Block.planks.blockID, 1, 2);
		world.setBlock(i + 13, j + 6, k + 23, Block.planks.blockID, 1, 2);
		world.setBlock(i + 13, j + 6, k + 24, Block.planks.blockID, 1, 2);
		world.setBlock(i + 13, j + 6, k + 25, Block.planks.blockID, 1, 2);
		world.setBlock(i + 13, j + 6, k + 26, Block.planks.blockID, 1, 2);
		world.setBlock(i + 13, j + 6, k + 27, Block.planks.blockID, 1, 2);
		world.setBlock(i + 13, j + 6, k + 28, Block.planks.blockID, 1, 2);
		world.setBlock(i + 13, j + 6, k + 29, Block.planks.blockID, 1, 2);
		world.setBlock(i + 13, j + 6, k + 30, Block.planks.blockID, 1, 2);
		world.setBlock(i + 13, j + 6, k + 31, Block.planks.blockID, 1, 2);
		world.setBlock(i + 13, j + 6, k + 32, Block.planks.blockID, 1, 2);
		world.setBlock(i + 13, j + 7, k + 2, Block.planks.blockID, 1, 2);
		world.setBlock(i + 13, j + 7, k + 4, Block.planks.blockID, 1, 2);
		world.setBlock(i + 13, j + 7, k + 5, Block.planks.blockID, 1, 2);
		world.setBlock(i + 13, j + 7, k + 6, Block.planks.blockID, 1, 2);
		world.setBlock(i + 13, j + 7, k + 7, Block.planks.blockID, 1, 2);
		world.setBlock(i + 13, j + 7, k + 8, Block.planks.blockID, 1, 2);
		world.setBlock(i + 13, j + 7, k + 9, Block.planks.blockID, 1, 2);
		world.setBlock(i + 13, j + 7, k + 10, Block.planks.blockID, 1, 2);
		world.setBlock(i + 13, j + 7, k + 11, Block.planks.blockID, 1, 2);
		world.setBlock(i + 13, j + 7, k + 12, Block.planks.blockID, 1, 2);
		world.setBlock(i + 13, j + 7, k + 13, Block.planks.blockID, 1, 2);
		world.setBlock(i + 13, j + 7, k + 14, Block.planks.blockID, 1, 2);
		world.setBlock(i + 13, j + 7, k + 15, Block.planks.blockID, 1, 2);
		world.setBlock(i + 13, j + 7, k + 16, Block.planks.blockID, 1, 2);
		world.setBlock(i + 13, j + 7, k + 17, Block.planks.blockID, 1, 2);
		world.setBlock(i + 13, j + 7, k + 18, Block.planks.blockID, 1, 2);
		world.setBlock(i + 13, j + 7, k + 19, Block.planks.blockID, 1, 2);
		world.setBlock(i + 13, j + 7, k + 20, Block.planks.blockID, 1, 2);
		world.setBlock(i + 13, j + 7, k + 21, Block.planks.blockID, 1, 2);
		world.setBlock(i + 13, j + 7, k + 22, Block.planks.blockID, 1, 2);
		world.setBlock(i + 13, j + 7, k + 23, Block.planks.blockID, 1, 2);
		world.setBlock(i + 13, j + 7, k + 24, Block.planks.blockID, 1, 2);
		world.setBlock(i + 13, j + 7, k + 25, Block.planks.blockID, 1, 2);
		world.setBlock(i + 13, j + 7, k + 26, Block.planks.blockID, 1, 2);
		world.setBlock(i + 13, j + 7, k + 27, Block.planks.blockID, 1, 2);
		world.setBlock(i + 13, j + 7, k + 28, Block.planks.blockID, 1, 2);
		world.setBlock(i + 13, j + 7, k + 29, Block.planks.blockID, 1, 2);
		world.setBlock(i + 13, j + 7, k + 30, Block.planks.blockID, 1, 2);
		world.setBlock(i + 13, j + 7, k + 31, Block.planks.blockID, 1, 2);
		world.setBlock(i + 13, j + 7, k + 32, Block.planks.blockID, 1, 2);
		world.setBlock(i + 13, j + 8, k + 2, Block.planks.blockID, 1, 2);
		world.setBlock(i + 13, j + 8, k + 4, Block.planks.blockID, 1, 2);
		world.setBlock(i + 13, j + 8, k + 5, Block.planks.blockID, 1, 2);
		world.setBlock(i + 13, j + 8, k + 6, Block.planks.blockID, 1, 2);
		world.setBlock(i + 13, j + 8, k + 7, Block.planks.blockID, 1, 2);
		world.setBlock(i + 13, j + 8, k + 8, Block.planks.blockID, 1, 2);
		world.setBlock(i + 13, j + 8, k + 9, Block.planks.blockID, 1, 2);
		world.setBlock(i + 13, j + 8, k + 10, Block.planks.blockID, 1, 2);
		world.setBlock(i + 13, j + 8, k + 11, Block.planks.blockID, 1, 2);
		world.setBlock(i + 13, j + 8, k + 12, Block.planks.blockID, 1, 2);
		world.setBlock(i + 13, j + 8, k + 13, Block.planks.blockID, 1, 2);
		world.setBlock(i + 13, j + 8, k + 14, Block.planks.blockID, 1, 2);
		world.setBlock(i + 13, j + 8, k + 15, Block.planks.blockID, 1, 2);
		world.setBlock(i + 13, j + 8, k + 16, Block.planks.blockID, 1, 2);
		world.setBlock(i + 13, j + 8, k + 18, Block.planks.blockID, 1, 2);
		world.setBlock(i + 13, j + 8, k + 19, Block.planks.blockID, 1, 2);
		world.setBlock(i + 13, j + 8, k + 20, Block.planks.blockID, 1, 2);
		world.setBlock(i + 13, j + 8, k + 21, Block.planks.blockID, 1, 2);
		world.setBlock(i + 13, j + 8, k + 22, Block.planks.blockID, 1, 2);
		world.setBlock(i + 13, j + 8, k + 23, Block.planks.blockID, 1, 2);
		world.setBlock(i + 13, j + 8, k + 24, Block.planks.blockID, 1, 2);
		world.setBlock(i + 13, j + 8, k + 25, Block.planks.blockID, 1, 2);
		world.setBlock(i + 13, j + 8, k + 26, Block.planks.blockID, 1, 2);
		world.setBlock(i + 13, j + 8, k + 27, Block.planks.blockID, 1, 2);
		world.setBlock(i + 13, j + 8, k + 28, Block.planks.blockID, 1, 2);
		world.setBlock(i + 13, j + 8, k + 29, Block.planks.blockID, 1, 2);
		world.setBlock(i + 13, j + 8, k + 30, Block.planks.blockID, 1, 2);
		world.setBlock(i + 13, j + 8, k + 31, Block.planks.blockID, 1, 2);
		world.setBlock(i + 13, j + 8, k + 32, Block.planks.blockID, 1, 2);
		world.setBlock(i + 13, j + 9, k + 2, Block.planks.blockID, 1, 2);
		world.setBlock(i + 13, j + 9, k + 3, Block.planks.blockID, 1, 2);
		world.setBlock(i + 13, j + 9, k + 4, Block.planks.blockID, 1, 2);
		world.setBlock(i + 13, j + 9, k + 5, Block.planks.blockID, 1, 2);
		world.setBlock(i + 13, j + 9, k + 6, Block.planks.blockID, 1, 2);
		world.setBlock(i + 13, j + 9, k + 7, Block.planks.blockID, 1, 2);
		world.setBlock(i + 13, j + 9, k + 8, Block.planks.blockID, 1, 2);
		world.setBlock(i + 13, j + 9, k + 9, Block.planks.blockID, 1, 2);
		world.setBlock(i + 13, j + 9, k + 10, Block.planks.blockID, 1, 2);
		world.setBlock(i + 13, j + 9, k + 11, Block.planks.blockID, 1, 2);
		world.setBlock(i + 13, j + 9, k + 12, Block.planks.blockID, 1, 2);
		world.setBlock(i + 13, j + 9, k + 13, Block.planks.blockID, 1, 2);
		world.setBlock(i + 13, j + 9, k + 14, Block.planks.blockID, 1, 2);
		world.setBlock(i + 13, j + 9, k + 15, Block.planks.blockID, 1, 2);
		world.setBlock(i + 13, j + 9, k + 16, Block.planks.blockID, 1, 2);
		world.setBlock(i + 13, j + 9, k + 18, Block.planks.blockID, 1, 2);
		world.setBlock(i + 13, j + 9, k + 19, Block.planks.blockID, 1, 2);
		world.setBlock(i + 13, j + 9, k + 20, Block.planks.blockID, 1, 2);
		world.setBlock(i + 13, j + 9, k + 21, Block.planks.blockID, 1, 2);
		world.setBlock(i + 13, j + 9, k + 22, Block.planks.blockID, 1, 2);
		world.setBlock(i + 13, j + 9, k + 23, Block.planks.blockID, 1, 2);
		world.setBlock(i + 13, j + 9, k + 24, Block.planks.blockID, 1, 2);
		world.setBlock(i + 13, j + 9, k + 25, Block.planks.blockID, 1, 2);
		world.setBlock(i + 13, j + 9, k + 26, Block.planks.blockID, 1, 2);
		world.setBlock(i + 13, j + 9, k + 27, Block.planks.blockID, 1, 2);
		world.setBlock(i + 13, j + 9, k + 28, Block.planks.blockID, 1, 2);
		world.setBlock(i + 13, j + 9, k + 29, Block.planks.blockID, 1, 2);
		world.setBlock(i + 13, j + 9, k + 30, Block.planks.blockID, 1, 2);
		world.setBlock(i + 13, j + 9, k + 31, Block.planks.blockID, 1, 2);
		world.setBlock(i + 13, j + 9, k + 32, Block.planks.blockID, 1, 2);
		world.setBlock(i + 13, j + 10, k + 3, Block.planks.blockID, 1, 2);
		world.setBlock(i + 13, j + 10, k + 4, Block.planks.blockID, 1, 2);
		world.setBlock(i + 13, j + 10, k + 5, Block.planks.blockID, 1, 2);
		world.setBlock(i + 13, j + 10, k + 6, Block.planks.blockID, 1, 2);
		world.setBlock(i + 13, j + 10, k + 7, Block.planks.blockID, 1, 2);
		world.setBlock(i + 13, j + 10, k + 8, Block.planks.blockID, 1, 2);
		world.setBlock(i + 13, j + 10, k + 9, Block.planks.blockID, 1, 2);
		world.setBlock(i + 13, j + 10, k + 10, Block.planks.blockID, 1, 2);
		world.setBlock(i + 13, j + 10, k + 11, Block.planks.blockID, 1, 2);
		world.setBlock(i + 13, j + 10, k + 12, Block.planks.blockID, 1, 2);
		world.setBlock(i + 13, j + 10, k + 13, Block.planks.blockID, 1, 2);
		world.setBlock(i + 13, j + 10, k + 14, Block.planks.blockID, 1, 2);
		world.setBlock(i + 13, j + 10, k + 15, Block.planks.blockID, 1, 2);
		world.setBlock(i + 13, j + 10, k + 16, Block.planks.blockID, 1, 2);
		world.setBlock(i + 13, j + 10, k + 19, Block.planks.blockID, 1, 2);
		world.setBlock(i + 13, j + 10, k + 20, Block.planks.blockID, 1, 2);
		world.setBlock(i + 13, j + 10, k + 21, Block.planks.blockID, 1, 2);
		world.setBlock(i + 13, j + 10, k + 22, Block.planks.blockID, 1, 2);
		world.setBlock(i + 13, j + 10, k + 23, Block.planks.blockID, 1, 2);
		world.setBlock(i + 13, j + 10, k + 24, Block.planks.blockID, 1, 2);
		world.setBlock(i + 13, j + 10, k + 25, Block.planks.blockID, 1, 2);
		world.setBlock(i + 13, j + 10, k + 26, Block.planks.blockID, 1, 2);
		world.setBlock(i + 13, j + 10, k + 27, Block.planks.blockID, 1, 2);
		world.setBlock(i + 13, j + 10, k + 28, Block.planks.blockID, 1, 2);
		world.setBlock(i + 13, j + 10, k + 29, Block.planks.blockID, 1, 2);
		world.setBlock(i + 13, j + 10, k + 30, Block.planks.blockID, 1, 2);
		world.setBlock(i + 13, j + 10, k + 31, Block.planks.blockID, 1, 2);
		world.setBlock(i + 13, j + 11, k + 3, Block.planks.blockID, 1, 2);
		world.setBlock(i + 13, j + 11, k + 4, Block.planks.blockID, 1, 2);
		world.setBlock(i + 13, j + 11, k + 5, Block.planks.blockID, 1, 2);
		world.setBlock(i + 13, j + 11, k + 6, Block.planks.blockID, 1, 2);
		world.setBlock(i + 13, j + 11, k + 7, Block.planks.blockID, 1, 2);
		world.setBlock(i + 13, j + 11, k + 8, Block.planks.blockID, 1, 2);
		world.setBlock(i + 13, j + 11, k + 9, Block.planks.blockID, 1, 2);
		world.setBlock(i + 13, j + 11, k + 10, Block.planks.blockID, 1, 2);
		world.setBlock(i + 13, j + 11, k + 11, Block.planks.blockID, 1, 2);
		world.setBlock(i + 13, j + 11, k + 12, Block.planks.blockID, 1, 2);
		world.setBlock(i + 13, j + 11, k + 13, Block.planks.blockID, 1, 2);
		world.setBlock(i + 13, j + 11, k + 14, Block.planks.blockID, 1, 2);
		world.setBlock(i + 13, j + 11, k + 15, Block.planks.blockID, 1, 2);
		world.setBlock(i + 13, j + 11, k + 16, Block.planks.blockID, 1, 2);
		world.setBlock(i + 13, j + 11, k + 17, Block.planks.blockID, 1, 2);
		world.setBlock(i + 13, j + 11, k + 18, Block.planks.blockID, 1, 2);
		world.setBlock(i + 13, j + 11, k + 19, Block.planks.blockID, 1, 2);
		world.setBlock(i + 13, j + 11, k + 20, Block.planks.blockID, 1, 2);
		world.setBlock(i + 13, j + 11, k + 21, Block.planks.blockID, 1, 2);
		world.setBlock(i + 13, j + 11, k + 22, Block.planks.blockID, 1, 2);
		world.setBlock(i + 13, j + 11, k + 23, Block.planks.blockID, 1, 2);
		world.setBlock(i + 13, j + 11, k + 24, Block.planks.blockID, 1, 2);
		world.setBlock(i + 13, j + 11, k + 25, Block.planks.blockID, 1, 2);
		world.setBlock(i + 13, j + 11, k + 26, Block.planks.blockID, 1, 2);
		world.setBlock(i + 13, j + 11, k + 27, Block.planks.blockID, 1, 2);
		world.setBlock(i + 13, j + 11, k + 28, Block.planks.blockID, 1, 2);
		world.setBlock(i + 13, j + 11, k + 29, Block.planks.blockID, 1, 2);
		world.setBlock(i + 13, j + 12, k + 5, Block.planks.blockID, 1, 2);
		world.setBlock(i + 13, j + 12, k + 6, Block.planks.blockID, 1, 2);
		world.setBlock(i + 13, j + 12, k + 7, Block.planks.blockID, 1, 2);
		world.setBlock(i + 13, j + 12, k + 8, Block.planks.blockID, 1, 2);
		world.setBlock(i + 13, j + 12, k + 9, Block.planks.blockID, 1, 2);
		world.setBlock(i + 13, j + 12, k + 10, Block.planks.blockID, 1, 2);
		world.setBlock(i + 13, j + 12, k + 11, Block.planks.blockID, 1, 2);
		world.setBlock(i + 13, j + 12, k + 12, Block.planks.blockID, 1, 2);
		world.setBlock(i + 13, j + 12, k + 13, Block.planks.blockID, 1, 2);
		world.setBlock(i + 13, j + 12, k + 14, Block.planks.blockID, 1, 2);
		world.setBlock(i + 13, j + 12, k + 15, Block.planks.blockID, 1, 2);
		world.setBlock(i + 13, j + 12, k + 16, Block.planks.blockID, 1, 2);
		world.setBlock(i + 13, j + 12, k + 17, Block.planks.blockID, 1, 2);
		world.setBlock(i + 13, j + 12, k + 18, Block.planks.blockID, 1, 2);
		world.setBlock(i + 13, j + 12, k + 19, Block.planks.blockID, 1, 2);
		world.setBlock(i + 13, j + 12, k + 20, Block.planks.blockID, 1, 2);
		world.setBlock(i + 13, j + 12, k + 21, Block.planks.blockID, 1, 2);
		world.setBlock(i + 13, j + 12, k + 22, Block.planks.blockID, 1, 2);
		world.setBlock(i + 13, j + 12, k + 23, Block.planks.blockID, 1, 2);
		world.setBlock(i + 13, j + 12, k + 24, Block.planks.blockID, 1, 2);
		world.setBlock(i + 13, j + 12, k + 25, Block.planks.blockID, 1, 2);
		world.setBlock(i + 13, j + 12, k + 26, Block.planks.blockID, 1, 2);
		world.setBlock(i + 13, j + 13, k + 8, Block.planks.blockID, 1, 2);
		world.setBlock(i + 13, j + 13, k + 9, Block.planks.blockID, 1, 2);
		world.setBlock(i + 13, j + 13, k + 10, Block.planks.blockID, 1, 2);
		world.setBlock(i + 13, j + 13, k + 11, Block.planks.blockID, 1, 2);
		world.setBlock(i + 13, j + 13, k + 12, Block.planks.blockID, 1, 2);
		world.setBlock(i + 13, j + 13, k + 13, Block.planks.blockID, 1, 2);
		world.setBlock(i + 13, j + 13, k + 14, Block.planks.blockID, 1, 2);
		world.setBlock(i + 13, j + 13, k + 15, Block.planks.blockID, 1, 2);
		world.setBlock(i + 13, j + 13, k + 16, Block.planks.blockID, 1, 2);
		world.setBlock(i + 13, j + 13, k + 17, Block.planks.blockID, 1, 2);
		world.setBlock(i + 13, j + 13, k + 18, Block.planks.blockID, 1, 2);
		world.setBlock(i + 13, j + 13, k + 19, Block.planks.blockID, 1, 2);
		world.setBlock(i + 13, j + 13, k + 20, Block.planks.blockID, 1, 2);
		world.setBlock(i + 13, j + 13, k + 21, Block.planks.blockID, 1, 2);
		world.setBlock(i + 13, j + 13, k + 22, Block.planks.blockID, 1, 2);
		world.setBlock(i + 13, j + 13, k + 23, Block.planks.blockID, 1, 2);
		world.setBlock(i + 13, j + 14, k + 10, Block.cloth.blockID, 5, 2);
		world.setBlock(i + 14, j + 2, k + 8, Block.planks.blockID, 1, 2);
		world.setBlock(i + 14, j + 2, k + 9, Block.planks.blockID, 1, 2);
		world.setBlock(i + 14, j + 2, k + 10, Block.planks.blockID, 1, 2);
		world.setBlock(i + 14, j + 2, k + 11, Block.planks.blockID, 1, 2);
		world.setBlock(i + 14, j + 2, k + 12, Block.planks.blockID, 1, 2);
		world.setBlock(i + 14, j + 2, k + 13, Block.planks.blockID, 1, 2);
		world.setBlock(i + 14, j + 2, k + 14, Block.planks.blockID, 1, 2);
		world.setBlock(i + 14, j + 2, k + 15, Block.planks.blockID, 1, 2);
		world.setBlock(i + 14, j + 2, k + 16, Block.planks.blockID, 1, 2);
		world.setBlock(i + 14, j + 2, k + 17, Block.planks.blockID, 1, 2);
		world.setBlock(i + 14, j + 2, k + 18, Block.planks.blockID, 1, 2);
		world.setBlock(i + 14, j + 2, k + 19, Block.planks.blockID, 1, 2);
		world.setBlock(i + 14, j + 2, k + 20, Block.planks.blockID, 1, 2);
		world.setBlock(i + 14, j + 2, k + 21, Block.planks.blockID, 1, 2);
		world.setBlock(i + 14, j + 2, k + 22, Block.planks.blockID, 1, 2);
		world.setBlock(i + 14, j + 2, k + 23, Block.planks.blockID, 1, 2);
		world.setBlock(i + 14, j + 3, k + 5, Block.planks.blockID, 1, 2);
		world.setBlock(i + 14, j + 3, k + 6, Block.planks.blockID, 1, 2);
		world.setBlock(i + 14, j + 3, k + 7, Block.planks.blockID, 1, 2);
		world.setBlock(i + 14, j + 3, k + 8, Block.planks.blockID, 1, 2);
		world.setBlock(i + 14, j + 3, k + 23, Block.planks.blockID, 1, 2);
		world.setBlock(i + 14, j + 3, k + 24, Block.planks.blockID, 1, 2);
		world.setBlock(i + 14, j + 3, k + 25, Block.planks.blockID, 1, 2);
		world.setBlock(i + 14, j + 3, k + 26, Block.planks.blockID, 1, 2);
		world.setBlock(i + 14, j + 4, k + 3, Block.planks.blockID, 1, 2);
		world.setBlock(i + 14, j + 4, k + 4, Block.planks.blockID, 1, 2);
		world.setBlock(i + 14, j + 4, k + 5, Block.planks.blockID, 1, 2);
		world.setBlock(i + 14, j + 4, k + 26, Block.planks.blockID, 1, 2);
		world.setBlock(i + 14, j + 4, k + 27, Block.planks.blockID, 1, 2);
		world.setBlock(i + 14, j + 4, k + 28, Block.planks.blockID, 1, 2);
		world.setBlock(i + 14, j + 4, k + 29, Block.planks.blockID, 1, 2);
		world.setBlock(i + 14, j + 5, k + 3, Block.planks.blockID, 1, 2);
		world.setBlock(i + 14, j + 5, k + 29, Block.planks.blockID, 1, 2);
		world.setBlock(i + 14, j + 5, k + 30, Block.planks.blockID, 1, 2);
		world.setBlock(i + 14, j + 5, k + 31, Block.planks.blockID, 1, 2);
		world.setBlock(i + 14, j + 6, k + 2, Block.planks.blockID, 1, 2);
		world.setBlock(i + 14, j + 6, k + 3, Block.planks.blockID, 1, 2);
		world.setBlock(i + 14, j + 6, k + 31, Block.planks.blockID, 1, 2);
		world.setBlock(i + 14, j + 6, k + 32, Block.planks.blockID, 1, 2);
		world.setBlock(i + 14, j + 7, k + 2, Block.planks.blockID, 1, 2);
		world.setBlock(i + 14, j + 7, k + 31, Block.chest.blockID, 2, 2);
		world.setBlock(i + 14, j + 7, k + 32, Block.planks.blockID, 1, 2);
		world.setBlock(i + 14, j + 8, k + 2, Block.planks.blockID, 1, 2);
		world.setBlock(i + 14, j + 8, k + 32, Block.planks.blockID, 1, 2);
		world.setBlock(i + 14, j + 9, k + 2, Block.planks.blockID, 1, 2);
		world.setBlock(i + 14, j + 9, k + 3, Block.planks.blockID, 1, 2);
		world.setBlock(i + 14, j + 9, k + 31, Block.planks.blockID, 1, 2);
		world.setBlock(i + 14, j + 9, k + 32, Block.planks.blockID, 1, 2);
		world.setBlock(i + 14, j + 10, k + 3, Block.planks.blockID, 1, 2);
		world.setBlock(i + 14, j + 10, k + 29, Block.planks.blockID, 1, 2);
		world.setBlock(i + 14, j + 10, k + 30, Block.planks.blockID, 1, 2);
		world.setBlock(i + 14, j + 10, k + 31, Block.planks.blockID, 1, 2);
		world.setBlock(i + 14, j + 11, k + 3, Block.planks.blockID, 1, 2);
		world.setBlock(i + 14, j + 11, k + 4, Block.planks.blockID, 1, 2);
		world.setBlock(i + 14, j + 11, k + 5, Block.planks.blockID, 1, 2);
		world.setBlock(i + 14, j + 11, k + 26, Block.planks.blockID, 1, 2);
		world.setBlock(i + 14, j + 11, k + 27, Block.planks.blockID, 1, 2);
		world.setBlock(i + 14, j + 11, k + 28, Block.planks.blockID, 1, 2);
		world.setBlock(i + 14, j + 11, k + 29, Block.planks.blockID, 1, 2);
		world.setBlock(i + 14, j + 12, k + 5, Block.planks.blockID, 1, 2);
		world.setBlock(i + 14, j + 12, k + 6, Block.planks.blockID, 1, 2);
		world.setBlock(i + 14, j + 12, k + 7, Block.planks.blockID, 1, 2);
		world.setBlock(i + 14, j + 12, k + 8, Block.planks.blockID, 1, 2);
		world.setBlock(i + 14, j + 12, k + 23, Block.planks.blockID, 1, 2);
		world.setBlock(i + 14, j + 12, k + 24, Block.planks.blockID, 1, 2);
		world.setBlock(i + 14, j + 12, k + 25, Block.planks.blockID, 1, 2);
		world.setBlock(i + 14, j + 12, k + 26, Block.planks.blockID, 1, 2);
		world.setBlock(i + 14, j + 13, k + 8, Block.planks.blockID, 1, 2);
		world.setBlock(i + 14, j + 13, k + 11, Block.planks.blockID, 1, 2);
		world.setBlock(i + 14, j + 13, k + 12, Block.planks.blockID, 1, 2);
		world.setBlock(i + 14, j + 13, k + 13, Block.planks.blockID, 1, 2);
		world.setBlock(i + 14, j + 13, k + 14, Block.planks.blockID, 1, 2);
		world.setBlock(i + 14, j + 13, k + 15, Block.planks.blockID, 1, 2);
		world.setBlock(i + 14, j + 13, k + 18, Block.planks.blockID, 1, 2);
		world.setBlock(i + 14, j + 13, k + 19, Block.planks.blockID, 1, 2);
		world.setBlock(i + 14, j + 13, k + 20, Block.planks.blockID, 1, 2);
		world.setBlock(i + 14, j + 13, k + 21, Block.planks.blockID, 1, 2);
		world.setBlock(i + 14, j + 13, k + 22, Block.planks.blockID, 1, 2);
		world.setBlock(i + 14, j + 13, k + 23, Block.planks.blockID, 1, 2);
		world.setBlock(i + 15, j + 2, k + 8, Block.planks.blockID, 1, 2);
		world.setBlock(i + 15, j + 2, k + 9, Block.planks.blockID, 1, 2);
		world.setBlock(i + 15, j + 2, k + 10, Block.planks.blockID, 1, 2);
		world.setBlock(i + 15, j + 2, k + 11, Block.planks.blockID, 1, 2);
		world.setBlock(i + 15, j + 2, k + 12, Block.planks.blockID, 1, 2);
		world.setBlock(i + 15, j + 2, k + 13, Block.planks.blockID, 1, 2);
		world.setBlock(i + 15, j + 2, k + 14, Block.planks.blockID, 1, 2);
		world.setBlock(i + 15, j + 2, k + 15, Block.planks.blockID, 1, 2);
		world.setBlock(i + 15, j + 2, k + 16, Block.planks.blockID, 1, 2);
		world.setBlock(i + 15, j + 2, k + 17, Block.planks.blockID, 1, 2);
		world.setBlock(i + 15, j + 2, k + 18, Block.planks.blockID, 1, 2);
		world.setBlock(i + 15, j + 2, k + 19, Block.planks.blockID, 1, 2);
		world.setBlock(i + 15, j + 2, k + 20, Block.planks.blockID, 1, 2);
		world.setBlock(i + 15, j + 2, k + 21, Block.planks.blockID, 1, 2);
		world.setBlock(i + 15, j + 2, k + 22, Block.planks.blockID, 1, 2);
		world.setBlock(i + 15, j + 2, k + 23, Block.planks.blockID, 1, 2);
		world.setBlock(i + 15, j + 3, k + 5, Block.planks.blockID, 1, 2);
		world.setBlock(i + 15, j + 3, k + 6, Block.planks.blockID, 1, 2);
		world.setBlock(i + 15, j + 3, k + 7, Block.planks.blockID, 1, 2);
		world.setBlock(i + 15, j + 3, k + 8, Block.planks.blockID, 1, 2);
		world.setBlock(i + 15, j + 3, k + 23, Block.planks.blockID, 1, 2);
		world.setBlock(i + 15, j + 3, k + 24, Block.planks.blockID, 1, 2);
		world.setBlock(i + 15, j + 3, k + 25, Block.planks.blockID, 1, 2);
		world.setBlock(i + 15, j + 3, k + 26, Block.planks.blockID, 1, 2);
		world.setBlock(i + 15, j + 4, k + 3, Block.planks.blockID, 1, 2);
		world.setBlock(i + 15, j + 4, k + 4, Block.planks.blockID, 1, 2);
		world.setBlock(i + 15, j + 4, k + 5, Block.planks.blockID, 1, 2);
		world.setBlock(i + 15, j + 4, k + 26, Block.planks.blockID, 1, 2);
		world.setBlock(i + 15, j + 4, k + 27, Block.planks.blockID, 1, 2);
		world.setBlock(i + 15, j + 4, k + 28, Block.planks.blockID, 1, 2);
		world.setBlock(i + 15, j + 4, k + 29, Block.planks.blockID, 1, 2);
		world.setBlock(i + 15, j + 5, k + 3, Block.planks.blockID, 1, 2);
		world.setBlock(i + 15, j + 5, k + 29, Block.planks.blockID, 1, 2);
		world.setBlock(i + 15, j + 5, k + 30, Block.planks.blockID, 1, 2);
		world.setBlock(i + 15, j + 5, k + 31, Block.planks.blockID, 1, 2);
		world.setBlock(i + 15, j + 6, k + 2, Block.planks.blockID, 1, 2);
		world.setBlock(i + 15, j + 6, k + 3, Block.planks.blockID, 1, 2);
		world.setBlock(i + 15, j + 6, k + 31, Block.planks.blockID, 1, 2);
		world.setBlock(i + 15, j + 6, k + 32, Block.planks.blockID, 1, 2);
		world.setBlock(i + 15, j + 7, k + 2, Block.planks.blockID, 1, 2);
		world.setBlock(i + 15, j + 7, k + 32, Block.planks.blockID, 1, 2);
		world.setBlock(i + 15, j + 8, k + 2, Block.planks.blockID, 1, 2);
		world.setBlock(i + 15, j + 8, k + 32, Block.planks.blockID, 1, 2);
		world.setBlock(i + 15, j + 9, k + 2, Block.planks.blockID, 1, 2);
		world.setBlock(i + 15, j + 9, k + 3, Block.planks.blockID, 1, 2);
		world.setBlock(i + 15, j + 9, k + 31, Block.planks.blockID, 1, 2);
		world.setBlock(i + 15, j + 9, k + 32, Block.planks.blockID, 1, 2);
		world.setBlock(i + 15, j + 10, k + 3, Block.planks.blockID, 1, 2);
		world.setBlock(i + 15, j + 10, k + 29, Block.planks.blockID, 1, 2);
		world.setBlock(i + 15, j + 10, k + 30, Block.planks.blockID, 1, 2);
		world.setBlock(i + 15, j + 10, k + 31, Block.planks.blockID, 1, 2);
		world.setBlock(i + 15, j + 11, k + 3, Block.planks.blockID, 1, 2);
		world.setBlock(i + 15, j + 11, k + 4, Block.planks.blockID, 1, 2);
		world.setBlock(i + 15, j + 11, k + 5, Block.planks.blockID, 1, 2);
		world.setBlock(i + 15, j + 11, k + 26, Block.planks.blockID, 1, 2);
		world.setBlock(i + 15, j + 11, k + 27, Block.planks.blockID, 1, 2);
		world.setBlock(i + 15, j + 11, k + 28, Block.planks.blockID, 1, 2);
		world.setBlock(i + 15, j + 11, k + 29, Block.planks.blockID, 1, 2);
		world.setBlock(i + 15, j + 12, k + 5, Block.planks.blockID, 1, 2);
		world.setBlock(i + 15, j + 12, k + 6, Block.planks.blockID, 1, 2);
		world.setBlock(i + 15, j + 12, k + 7, Block.planks.blockID, 1, 2);
		world.setBlock(i + 15, j + 12, k + 8, Block.planks.blockID, 1, 2);
		world.setBlock(i + 15, j + 12, k + 23, Block.planks.blockID, 1, 2);
		world.setBlock(i + 15, j + 12, k + 24, Block.planks.blockID, 1, 2);
		world.setBlock(i + 15, j + 12, k + 25, Block.planks.blockID, 1, 2);
		world.setBlock(i + 15, j + 12, k + 26, Block.planks.blockID, 1, 2);
		world.setBlock(i + 15, j + 13, k + 8, Block.planks.blockID, 1, 2);
		world.setBlock(i + 15, j + 13, k + 9, Block.planks.blockID, 1, 2);
		world.setBlock(i + 15, j + 13, k + 10, Block.planks.blockID, 1, 2);
		world.setBlock(i + 15, j + 13, k + 11, Block.planks.blockID, 1, 2);
		world.setBlock(i + 15, j + 13, k + 12, Block.planks.blockID, 1, 2);
		world.setBlock(i + 15, j + 13, k + 13, Block.planks.blockID, 1, 2);
		world.setBlock(i + 15, j + 13, k + 14, Block.planks.blockID, 1, 2);
		world.setBlock(i + 15, j + 13, k + 15, Block.planks.blockID, 1, 2);
		world.setBlock(i + 15, j + 13, k + 16, Block.planks.blockID, 1, 2);
		world.setBlock(i + 15, j + 13, k + 19, Block.planks.blockID, 1, 2);
		world.setBlock(i + 15, j + 13, k + 20, Block.planks.blockID, 1, 2);
		world.setBlock(i + 15, j + 13, k + 21, Block.planks.blockID, 1, 2);
		world.setBlock(i + 15, j + 13, k + 22, Block.planks.blockID, 1, 2);
		world.setBlock(i + 15, j + 13, k + 23, Block.planks.blockID, 1, 2);
		world.setBlock(i + 16, j + 2, k + 10, Block.planks.blockID, 1, 2);
		world.setBlock(i + 16, j + 2, k + 11, Block.planks.blockID, 1, 2);
		world.setBlock(i + 16, j + 2, k + 12, Block.planks.blockID, 1, 2);
		world.setBlock(i + 16, j + 2, k + 13, Block.planks.blockID, 1, 2);
		world.setBlock(i + 16, j + 2, k + 14, Block.planks.blockID, 1, 2);
		world.setBlock(i + 16, j + 2, k + 15, Block.planks.blockID, 1, 2);
		world.setBlock(i + 16, j + 2, k + 16, Block.planks.blockID, 1, 2);
		world.setBlock(i + 16, j + 2, k + 17, Block.planks.blockID, 1, 2);
		world.setBlock(i + 16, j + 2, k + 18, Block.planks.blockID, 1, 2);
		world.setBlock(i + 16, j + 2, k + 19, Block.planks.blockID, 1, 2);
		world.setBlock(i + 16, j + 2, k + 20, Block.planks.blockID, 1, 2);
		world.setBlock(i + 16, j + 2, k + 21, Block.planks.blockID, 1, 2);
		world.setBlock(i + 16, j + 3, k + 3, Block.cloth.blockID, 5, 2);
		world.setBlock(i + 16, j + 3, k + 9, Block.planks.blockID, 1, 2);
		world.setBlock(i + 16, j + 3, k + 22, Block.planks.blockID, 1, 2);
		world.setBlock(i + 16, j + 4, k + 3, Block.cloth.blockID, 5, 2);
		world.setBlock(i + 16, j + 4, k + 4, Block.cloth.blockID, 5, 2);
		world.setBlock(i + 16, j + 4, k + 6, Block.planks.blockID, 1, 2);
		world.setBlock(i + 16, j + 4, k + 7, Block.planks.blockID, 1, 2);
		world.setBlock(i + 16, j + 4, k + 8, Block.planks.blockID, 1, 2);
		world.setBlock(i + 16, j + 4, k + 9, Block.planks.blockID, 1, 2);
		world.setBlock(i + 16, j + 4, k + 22, Block.planks.blockID, 1, 2);
		world.setBlock(i + 16, j + 4, k + 23, Block.planks.blockID, 1, 2);
		world.setBlock(i + 16, j + 4, k + 24, Block.planks.blockID, 1, 2);
		world.setBlock(i + 16, j + 4, k + 25, Block.planks.blockID, 1, 2);
		world.setBlock(i + 16, j + 5, k + 3, Block.cloth.blockID, 5, 2);
		world.setBlock(i + 16, j + 5, k + 4, Block.planks.blockID, 1, 2);
		world.setBlock(i + 16, j + 5, k + 5, Block.planks.blockID, 1, 2);
		world.setBlock(i + 16, j + 5, k + 6, Block.planks.blockID, 1, 2);
		world.setBlock(i + 16, j + 5, k + 7, Block.planks.blockID, 1, 2);
		world.setBlock(i + 16, j + 5, k + 8, Block.planks.blockID, 1, 2);
		world.setBlock(i + 16, j + 5, k + 9, Block.planks.blockID, 1, 2);
		world.setBlock(i + 16, j + 5, k + 22, Block.planks.blockID, 1, 2);
		world.setBlock(i + 16, j + 5, k + 23, Block.planks.blockID, 1, 2);
		world.setBlock(i + 16, j + 5, k + 24, Block.planks.blockID, 1, 2);
		world.setBlock(i + 16, j + 5, k + 25, Block.planks.blockID, 1, 2);
		world.setBlock(i + 16, j + 5, k + 26, Block.planks.blockID, 1, 2);
		world.setBlock(i + 16, j + 5, k + 27, Block.planks.blockID, 1, 2);
		world.setBlock(i + 16, j + 5, k + 28, Block.planks.blockID, 1, 2);
		world.setBlock(i + 16, j + 6, k + 4, Block.planks.blockID, 1, 2);
		world.setBlock(i + 16, j + 6, k + 5, Block.planks.blockID, 1, 2);
		world.setBlock(i + 16, j + 6, k + 6, Block.planks.blockID, 1, 2);
		world.setBlock(i + 16, j + 6, k + 7, Block.planks.blockID, 1, 2);
		world.setBlock(i + 16, j + 6, k + 8, Block.planks.blockID, 1, 2);
		world.setBlock(i + 16, j + 6, k + 9, Block.planks.blockID, 1, 2);
		world.setBlock(i + 16, j + 6, k + 22, Block.planks.blockID, 1, 2);
		world.setBlock(i + 16, j + 6, k + 23, Block.planks.blockID, 1, 2);
		world.setBlock(i + 16, j + 6, k + 24, Block.planks.blockID, 1, 2);
		world.setBlock(i + 16, j + 6, k + 25, Block.planks.blockID, 1, 2);
		world.setBlock(i + 16, j + 6, k + 26, Block.planks.blockID, 1, 2);
		world.setBlock(i + 16, j + 6, k + 27, Block.planks.blockID, 1, 2);
		world.setBlock(i + 16, j + 6, k + 28, Block.planks.blockID, 1, 2);
		world.setBlock(i + 16, j + 6, k + 29, Block.planks.blockID, 1, 2);
		world.setBlock(i + 16, j + 6, k + 30, Block.planks.blockID, 1, 2);
		world.setBlock(i + 16, j + 7, k + 3, Block.planks.blockID, 1, 2);
		world.setBlock(i + 16, j + 7, k + 4, Block.planks.blockID, 1, 2);
		world.setBlock(i + 16, j + 7, k + 5, Block.planks.blockID, 1, 2);
		world.setBlock(i + 16, j + 7, k + 6, Block.planks.blockID, 1, 2);
		world.setBlock(i + 16, j + 7, k + 7, Block.planks.blockID, 1, 2);
		world.setBlock(i + 16, j + 7, k + 8, Block.planks.blockID, 1, 2);
		world.setBlock(i + 16, j + 7, k + 9, Block.planks.blockID, 1, 2);
		world.setBlock(i + 16, j + 7, k + 22, Block.planks.blockID, 1, 2);
		world.setBlock(i + 16, j + 7, k + 23, Block.planks.blockID, 1, 2);
		world.setBlock(i + 16, j + 7, k + 24, Block.planks.blockID, 1, 2);
		world.setBlock(i + 16, j + 7, k + 25, Block.planks.blockID, 1, 2);
		world.setBlock(i + 16, j + 7, k + 26, Block.planks.blockID, 1, 2);
		world.setBlock(i + 16, j + 7, k + 27, Block.planks.blockID, 1, 2);
		world.setBlock(i + 16, j + 7, k + 28, Block.planks.blockID, 1, 2);
		world.setBlock(i + 16, j + 7, k + 29, Block.planks.blockID, 1, 2);
		world.setBlock(i + 16, j + 7, k + 30, Block.planks.blockID, 1, 2);
		world.setBlock(i + 16, j + 7, k + 31, Block.planks.blockID, 1, 2);
		world.setBlock(i + 16, j + 8, k + 3, Block.planks.blockID, 1, 2);
		world.setBlock(i + 16, j + 8, k + 4, Block.planks.blockID, 1, 2);
		world.setBlock(i + 16, j + 8, k + 5, Block.planks.blockID, 1, 2);
		world.setBlock(i + 16, j + 8, k + 6, Block.planks.blockID, 1, 2);
		world.setBlock(i + 16, j + 8, k + 7, Block.planks.blockID, 1, 2);
		world.setBlock(i + 16, j + 8, k + 8, Block.planks.blockID, 1, 2);
		world.setBlock(i + 16, j + 8, k + 9, Block.planks.blockID, 1, 2);
		world.setBlock(i + 16, j + 8, k + 22, Block.planks.blockID, 1, 2);
		world.setBlock(i + 16, j + 8, k + 23, Block.planks.blockID, 1, 2);
		world.setBlock(i + 16, j + 8, k + 24, Block.planks.blockID, 1, 2);
		world.setBlock(i + 16, j + 8, k + 25, Block.planks.blockID, 1, 2);
		world.setBlock(i + 16, j + 8, k + 26, Block.planks.blockID, 1, 2);
		world.setBlock(i + 16, j + 8, k + 27, Block.planks.blockID, 1, 2);
		world.setBlock(i + 16, j + 8, k + 28, Block.planks.blockID, 1, 2);
		world.setBlock(i + 16, j + 8, k + 29, Block.planks.blockID, 1, 2);
		world.setBlock(i + 16, j + 8, k + 30, Block.planks.blockID, 1, 2);
		world.setBlock(i + 16, j + 8, k + 31, Block.planks.blockID, 1, 2);
		world.setBlock(i + 16, j + 9, k + 4, Block.planks.blockID, 1, 2);
		world.setBlock(i + 16, j + 9, k + 5, Block.planks.blockID, 1, 2);
		world.setBlock(i + 16, j + 9, k + 6, Block.planks.blockID, 1, 2);
		world.setBlock(i + 16, j + 9, k + 7, Block.planks.blockID, 1, 2);
		world.setBlock(i + 16, j + 9, k + 8, Block.planks.blockID, 1, 2);
		world.setBlock(i + 16, j + 9, k + 9, Block.planks.blockID, 1, 2);
		world.setBlock(i + 16, j + 9, k + 22, Block.planks.blockID, 1, 2);
		world.setBlock(i + 16, j + 9, k + 23, Block.planks.blockID, 1, 2);
		world.setBlock(i + 16, j + 9, k + 24, Block.planks.blockID, 1, 2);
		world.setBlock(i + 16, j + 9, k + 25, Block.planks.blockID, 1, 2);
		world.setBlock(i + 16, j + 9, k + 26, Block.planks.blockID, 1, 2);
		world.setBlock(i + 16, j + 9, k + 27, Block.planks.blockID, 1, 2);
		world.setBlock(i + 16, j + 9, k + 28, Block.planks.blockID, 1, 2);
		world.setBlock(i + 16, j + 9, k + 29, Block.planks.blockID, 1, 2);
		world.setBlock(i + 16, j + 9, k + 30, Block.planks.blockID, 1, 2);
		world.setBlock(i + 16, j + 10, k + 4, Block.planks.blockID, 1, 2);
		world.setBlock(i + 16, j + 10, k + 5, Block.planks.blockID, 1, 2);
		world.setBlock(i + 16, j + 10, k + 6, Block.planks.blockID, 1, 2);
		world.setBlock(i + 16, j + 10, k + 7, Block.planks.blockID, 1, 2);
		world.setBlock(i + 16, j + 10, k + 8, Block.planks.blockID, 1, 2);
		world.setBlock(i + 16, j + 10, k + 9, Block.planks.blockID, 1, 2);
		world.setBlock(i + 16, j + 10, k + 22, Block.planks.blockID, 1, 2);
		world.setBlock(i + 16, j + 10, k + 23, Block.planks.blockID, 1, 2);
		world.setBlock(i + 16, j + 10, k + 24, Block.planks.blockID, 1, 2);
		world.setBlock(i + 16, j + 10, k + 25, Block.planks.blockID, 1, 2);
		world.setBlock(i + 16, j + 10, k + 26, Block.planks.blockID, 1, 2);
		world.setBlock(i + 16, j + 10, k + 27, Block.planks.blockID, 1, 2);
		world.setBlock(i + 16, j + 10, k + 28, Block.planks.blockID, 1, 2);
		world.setBlock(i + 16, j + 11, k + 6, Block.planks.blockID, 1, 2);
		world.setBlock(i + 16, j + 11, k + 7, Block.planks.blockID, 1, 2);
		world.setBlock(i + 16, j + 11, k + 8, Block.planks.blockID, 1, 2);
		world.setBlock(i + 16, j + 11, k + 9, Block.planks.blockID, 1, 2);
		world.setBlock(i + 16, j + 11, k + 22, Block.planks.blockID, 1, 2);
		world.setBlock(i + 16, j + 11, k + 23, Block.planks.blockID, 1, 2);
		world.setBlock(i + 16, j + 11, k + 24, Block.planks.blockID, 1, 2);
		world.setBlock(i + 16, j + 11, k + 25, Block.planks.blockID, 1, 2);
		world.setBlock(i + 16, j + 12, k + 9, Block.planks.blockID, 1, 2);
		world.setBlock(i + 16, j + 12, k + 22, Block.planks.blockID, 1, 2);
		world.setBlock(i + 16, j + 13, k + 10, Block.planks.blockID, 1, 2);
		world.setBlock(i + 16, j + 13, k + 11, Block.planks.blockID, 1, 2);
		world.setBlock(i + 16, j + 13, k + 12, Block.planks.blockID, 1, 2);
		world.setBlock(i + 16, j + 13, k + 13, Block.planks.blockID, 1, 2);
		world.setBlock(i + 16, j + 13, k + 14, Block.planks.blockID, 1, 2);
		world.setBlock(i + 16, j + 13, k + 15, Block.planks.blockID, 1, 2);
		world.setBlock(i + 16, j + 13, k + 16, Block.planks.blockID, 1, 2);
		world.setBlock(i + 16, j + 13, k + 17, Block.planks.blockID, 1, 2);
		world.setBlock(i + 16, j + 13, k + 18, Block.planks.blockID, 1, 2);
		world.setBlock(i + 16, j + 13, k + 19, Block.planks.blockID, 1, 2);
		world.setBlock(i + 16, j + 13, k + 20, Block.planks.blockID, 1, 2);
		world.setBlock(i + 16, j + 13, k + 21, Block.planks.blockID, 1, 2);
		world.setBlock(i + 17, j + 2, k + 11, Block.planks.blockID, 1, 2);
		world.setBlock(i + 17, j + 2, k + 12, Block.planks.blockID, 1, 2);
		world.setBlock(i + 17, j + 2, k + 13, Block.planks.blockID, 1, 2);
		world.setBlock(i + 17, j + 2, k + 14, Block.planks.blockID, 1, 2);
		world.setBlock(i + 17, j + 2, k + 15, Block.planks.blockID, 1, 2);
		world.setBlock(i + 17, j + 2, k + 16, Block.planks.blockID, 1, 2);
		world.setBlock(i + 17, j + 2, k + 17, Block.planks.blockID, 1, 2);
		world.setBlock(i + 17, j + 2, k + 18, Block.planks.blockID, 1, 2);
		world.setBlock(i + 17, j + 2, k + 19, Block.planks.blockID, 1, 2);
		world.setBlock(i + 17, j + 2, k + 20, Block.planks.blockID, 1, 2);
		world.setBlock(i + 17, j + 3, k + 10, Block.planks.blockID, 1, 2);
		world.setBlock(i + 17, j + 3, k + 21, Block.planks.blockID, 1, 2);
		world.setBlock(i + 17, j + 4, k + 10, Block.planks.blockID, 1, 2);
		world.setBlock(i + 17, j + 4, k + 21, Block.planks.blockID, 1, 2);
		world.setBlock(i + 17, j + 5, k + 10, Block.planks.blockID, 1, 2);
		world.setBlock(i + 17, j + 5, k + 21, Block.planks.blockID, 1, 2);
		world.setBlock(i + 17, j + 6, k + 10, Block.planks.blockID, 1, 2);
		world.setBlock(i + 17, j + 6, k + 21, Block.planks.blockID, 1, 2);
		world.setBlock(i + 17, j + 7, k + 10, Block.planks.blockID, 1, 2);
		world.setBlock(i + 17, j + 7, k + 21, Block.planks.blockID, 1, 2);
		world.setBlock(i + 17, j + 8, k + 10, Block.planks.blockID, 1, 2);
		world.setBlock(i + 17, j + 8, k + 21, Block.planks.blockID, 1, 2);
		world.setBlock(i + 17, j + 9, k + 10, Block.planks.blockID, 1, 2);
		world.setBlock(i + 17, j + 9, k + 21, Block.planks.blockID, 1, 2);
		world.setBlock(i + 17, j + 10, k + 10, Block.planks.blockID, 1, 2);
		world.setBlock(i + 17, j + 10, k + 21, Block.planks.blockID, 1, 2);
		world.setBlock(i + 17, j + 11, k + 10, Block.planks.blockID, 1, 2);
		world.setBlock(i + 17, j + 11, k + 21, Block.planks.blockID, 1, 2);
		world.setBlock(i + 17, j + 12, k + 10, Block.planks.blockID, 1, 2);
		world.setBlock(i + 17, j + 12, k + 21, Block.planks.blockID, 1, 2);
		world.setBlock(i + 17, j + 13, k + 11, Block.planks.blockID, 1, 2);
		world.setBlock(i + 17, j + 13, k + 12, Block.planks.blockID, 1, 2);
		world.setBlock(i + 17, j + 13, k + 13, Block.planks.blockID, 1, 2);
		world.setBlock(i + 17, j + 13, k + 14, Block.planks.blockID, 1, 2);
		world.setBlock(i + 17, j + 13, k + 15, Block.planks.blockID, 1, 2);
		world.setBlock(i + 17, j + 13, k + 16, Block.planks.blockID, 1, 2);
		world.setBlock(i + 17, j + 13, k + 17, Block.planks.blockID, 1, 2);
		world.setBlock(i + 17, j + 13, k + 18, Block.planks.blockID, 1, 2);
		world.setBlock(i + 17, j + 13, k + 19, Block.planks.blockID, 1, 2);
		world.setBlock(i + 17, j + 13, k + 20, Block.planks.blockID, 1, 2);
		world.setBlock(i + 18, j + 3, k + 11, Block.planks.blockID, 1, 2);
		world.setBlock(i + 18, j + 3, k + 12, Block.planks.blockID, 1, 2);
		world.setBlock(i + 18, j + 3, k + 13, Block.planks.blockID, 1, 2);
		world.setBlock(i + 18, j + 3, k + 14, Block.planks.blockID, 1, 2);
		world.setBlock(i + 18, j + 3, k + 15, Block.planks.blockID, 1, 2);
		world.setBlock(i + 18, j + 3, k + 16, Block.planks.blockID, 1, 2);
		world.setBlock(i + 18, j + 3, k + 17, Block.planks.blockID, 1, 2);
		world.setBlock(i + 18, j + 3, k + 18, Block.planks.blockID, 1, 2);
		world.setBlock(i + 18, j + 3, k + 19, Block.planks.blockID, 1, 2);
		world.setBlock(i + 18, j + 3, k + 20, Block.planks.blockID, 1, 2);
		world.setBlock(i + 18, j + 4, k + 11, Block.planks.blockID, 1, 2);
		world.setBlock(i + 18, j + 4, k + 12, Block.planks.blockID, 1, 2);
		world.setBlock(i + 18, j + 4, k + 13, Block.planks.blockID, 1, 2);
		world.setBlock(i + 18, j + 4, k + 14, Block.planks.blockID, 1, 2);
		world.setBlock(i + 18, j + 4, k + 15, Block.planks.blockID, 1, 2);
		world.setBlock(i + 18, j + 4, k + 16, Block.planks.blockID, 1, 2);
		world.setBlock(i + 18, j + 4, k + 17, Block.planks.blockID, 1, 2);
		world.setBlock(i + 18, j + 4, k + 18, Block.planks.blockID, 1, 2);
		world.setBlock(i + 18, j + 4, k + 19, Block.planks.blockID, 1, 2);
		world.setBlock(i + 18, j + 4, k + 20, Block.planks.blockID, 1, 2);
		world.setBlock(i + 18, j + 5, k + 11, Block.planks.blockID, 1, 2);
		world.setBlock(i + 18, j + 5, k + 12, Block.planks.blockID, 1, 2);
		world.setBlock(i + 18, j + 5, k + 13, Block.planks.blockID, 1, 2);
		world.setBlock(i + 18, j + 5, k + 14, Block.planks.blockID, 1, 2);
		world.setBlock(i + 18, j + 5, k + 15, Block.planks.blockID, 1, 2);
		world.setBlock(i + 18, j + 5, k + 16, Block.planks.blockID, 1, 2);
		world.setBlock(i + 18, j + 5, k + 17, Block.planks.blockID, 1, 2);
		world.setBlock(i + 18, j + 5, k + 18, Block.planks.blockID, 1, 2);
		world.setBlock(i + 18, j + 5, k + 19, Block.planks.blockID, 1, 2);
		world.setBlock(i + 18, j + 5, k + 20, Block.planks.blockID, 1, 2);
		world.setBlock(i + 18, j + 6, k + 11, Block.planks.blockID, 1, 2);
		world.setBlock(i + 18, j + 6, k + 12, Block.planks.blockID, 1, 2);
		world.setBlock(i + 18, j + 6, k + 13, Block.planks.blockID, 1, 2);
		world.setBlock(i + 18, j + 6, k + 14, Block.planks.blockID, 1, 2);
		world.setBlock(i + 18, j + 6, k + 15, Block.planks.blockID, 1, 2);
		world.setBlock(i + 18, j + 6, k + 16, Block.planks.blockID, 1, 2);
		world.setBlock(i + 18, j + 6, k + 17, Block.planks.blockID, 1, 2);
		world.setBlock(i + 18, j + 6, k + 18, Block.planks.blockID, 1, 2);
		world.setBlock(i + 18, j + 6, k + 19, Block.planks.blockID, 1, 2);
		world.setBlock(i + 18, j + 6, k + 20, Block.planks.blockID, 1, 2);
		world.setBlock(i + 18, j + 7, k + 11, Block.planks.blockID, 1, 2);
		world.setBlock(i + 18, j + 7, k + 12, Block.planks.blockID, 1, 2);
		world.setBlock(i + 18, j + 7, k + 13, Block.planks.blockID, 1, 2);
		world.setBlock(i + 18, j + 7, k + 14, Block.planks.blockID, 1, 2);
		world.setBlock(i + 18, j + 7, k + 15, Block.planks.blockID, 1, 2);
		world.setBlock(i + 18, j + 7, k + 16, Block.planks.blockID, 1, 2);
		world.setBlock(i + 18, j + 7, k + 17, Block.planks.blockID, 1, 2);
		world.setBlock(i + 18, j + 7, k + 18, Block.planks.blockID, 1, 2);
		world.setBlock(i + 18, j + 7, k + 19, Block.planks.blockID, 1, 2);
		world.setBlock(i + 18, j + 7, k + 20, Block.planks.blockID, 1, 2);
		world.setBlock(i + 18, j + 8, k + 11, Block.planks.blockID, 1, 2);
		world.setBlock(i + 18, j + 8, k + 12, Block.planks.blockID, 1, 2);
		world.setBlock(i + 18, j + 8, k + 13, Block.planks.blockID, 1, 2);
		world.setBlock(i + 18, j + 8, k + 14, Block.planks.blockID, 1, 2);
		world.setBlock(i + 18, j + 8, k + 15, Block.planks.blockID, 1, 2);
		world.setBlock(i + 18, j + 8, k + 16, Block.planks.blockID, 1, 2);
		world.setBlock(i + 18, j + 8, k + 17, Block.planks.blockID, 1, 2);
		world.setBlock(i + 18, j + 8, k + 18, Block.planks.blockID, 1, 2);
		world.setBlock(i + 18, j + 8, k + 19, Block.planks.blockID, 1, 2);
		world.setBlock(i + 18, j + 8, k + 20, Block.planks.blockID, 1, 2);
		world.setBlock(i + 18, j + 9, k + 11, Block.planks.blockID, 1, 2);
		world.setBlock(i + 18, j + 9, k + 12, Block.planks.blockID, 1, 2);
		world.setBlock(i + 18, j + 9, k + 13, Block.planks.blockID, 1, 2);
		world.setBlock(i + 18, j + 9, k + 14, Block.planks.blockID, 1, 2);
		world.setBlock(i + 18, j + 9, k + 15, Block.planks.blockID, 1, 2);
		world.setBlock(i + 18, j + 9, k + 17, Block.planks.blockID, 1, 2);
		world.setBlock(i + 18, j + 9, k + 18, Block.planks.blockID, 1, 2);
		world.setBlock(i + 18, j + 9, k + 19, Block.planks.blockID, 1, 2);
		world.setBlock(i + 18, j + 9, k + 20, Block.planks.blockID, 1, 2);
		world.setBlock(i + 18, j + 10, k + 11, Block.planks.blockID, 1, 2);
		world.setBlock(i + 18, j + 10, k + 12, Block.planks.blockID, 1, 2);
		world.setBlock(i + 18, j + 10, k + 13, Block.planks.blockID, 1, 2);
		world.setBlock(i + 18, j + 10, k + 14, Block.planks.blockID, 1, 2);
		world.setBlock(i + 18, j + 10, k + 17, Block.planks.blockID, 1, 2);
		world.setBlock(i + 18, j + 10, k + 18, Block.planks.blockID, 1, 2);
		world.setBlock(i + 18, j + 10, k + 19, Block.planks.blockID, 1, 2);
		world.setBlock(i + 18, j + 10, k + 20, Block.planks.blockID, 1, 2);
		world.setBlock(i + 18, j + 11, k + 11, Block.planks.blockID, 1, 2);
		world.setBlock(i + 18, j + 11, k + 12, Block.planks.blockID, 1, 2);
		world.setBlock(i + 18, j + 11, k + 13, Block.planks.blockID, 1, 2);
		world.setBlock(i + 18, j + 11, k + 14, Block.planks.blockID, 1, 2);
		world.setBlock(i + 18, j + 11, k + 15, Block.planks.blockID, 1, 2);
		world.setBlock(i + 18, j + 11, k + 16, Block.planks.blockID, 1, 2);
		world.setBlock(i + 18, j + 11, k + 17, Block.planks.blockID, 1, 2);
		world.setBlock(i + 18, j + 11, k + 18, Block.planks.blockID, 1, 2);
		world.setBlock(i + 18, j + 11, k + 19, Block.planks.blockID, 1, 2);
		world.setBlock(i + 18, j + 11, k + 20, Block.planks.blockID, 1, 2);
		world.setBlock(i + 18, j + 12, k + 11, Block.planks.blockID, 1, 2);
		world.setBlock(i + 18, j + 12, k + 12, Block.planks.blockID, 1, 2);
		world.setBlock(i + 18, j + 12, k + 13, Block.planks.blockID, 1, 2);
		world.setBlock(i + 18, j + 12, k + 14, Block.planks.blockID, 1, 2);
		world.setBlock(i + 18, j + 12, k + 15, Block.planks.blockID, 1, 2);
		world.setBlock(i + 18, j + 12, k + 16, Block.planks.blockID, 1, 2);
		world.setBlock(i + 18, j + 12, k + 17, Block.planks.blockID, 1, 2);
		world.setBlock(i + 18, j + 12, k + 18, Block.planks.blockID, 1, 2);
		world.setBlock(i + 18, j + 12, k + 19, Block.planks.blockID, 1, 2);
		world.setBlock(i + 18, j + 12, k + 20, Block.planks.blockID, 1, 2);
		world.setBlock(i + 12, j + 7, k + 3, Block.ladder.blockID, 3, 1);
		world.setBlock(i + 13, j + 7, k + 3, Block.ladder.blockID, 3, 1);
		world.setBlock(i + 14, j + 8, k + 3, Block.ladder.blockID, 3, 1);
		world.setBlock(i + 15, j + 7, k + 3, Block.ladder.blockID, 3, 1);
		world.setBlock(i + 15, j + 8, k + 3, Block.ladder.blockID, 3, 1);

		return true;
	}
}